[2023-06-11T04:48:41.955+0000] {taskinstance.py:1103} INFO - Dependencies all met for dep_context=non-requeueable deps ti=<TaskInstance: first_dag_02.thrid_task scheduled__2021-09-14T00:00:00+00:00 [queued]>
[2023-06-11T04:48:42.054+0000] {taskinstance.py:1103} INFO - Dependencies all met for dep_context=requeueable deps ti=<TaskInstance: first_dag_02.thrid_task scheduled__2021-09-14T00:00:00+00:00 [queued]>
[2023-06-11T04:48:42.219+0000] {taskinstance.py:1308} INFO - Starting attempt 1 of 6
[2023-06-11T04:48:45.200+0000] {taskinstance.py:1327} INFO - Executing <Task(BashOperator): thrid_task> on 2021-09-14 00:00:00+00:00
[2023-06-11T04:48:45.216+0000] {standard_task_runner.py:57} INFO - Started process 657 to run task
[2023-06-11T04:48:45.245+0000] {standard_task_runner.py:84} INFO - Running: ['***', 'tasks', 'run', 'first_dag_02', 'thrid_task', 'scheduled__2021-09-14T00:00:00+00:00', '--job-id', '187', '--raw', '--subdir', 'DAGS_FOLDER/First_dag.py', '--cfg-path', '/tmp/tmpj4npa60q']
[2023-06-11T04:48:45.247+0000] {standard_task_runner.py:85} INFO - Job 187: Subtask thrid_task
[2023-06-11T04:48:46.387+0000] {task_command.py:410} INFO - Running <TaskInstance: first_dag_02.thrid_task scheduled__2021-09-14T00:00:00+00:00 [running]> on host 4b1b5d40d165
[2023-06-11T04:48:50.926+0000] {taskinstance.py:1547} INFO - Exporting env vars: AIRFLOW_CTX_DAG_OWNER='Raja' AIRFLOW_CTX_DAG_ID='first_dag_02' AIRFLOW_CTX_TASK_ID='thrid_task' AIRFLOW_CTX_EXECUTION_DATE='2021-09-14T00:00:00+00:00' AIRFLOW_CTX_TRY_NUMBER='1' AIRFLOW_CTX_DAG_RUN_ID='scheduled__2021-09-14T00:00:00+00:00'
[2023-06-11T04:48:50.956+0000] {subprocess.py:63} INFO - Tmp dir root location: 
 /tmp
[2023-06-11T04:48:51.076+0000] {subprocess.py:75} INFO - Running command: ['/bin/bash', '-c', 'echo hey, I am task3 and will be running after task1 at the same time as task2!']
[2023-06-11T04:48:51.759+0000] {subprocess.py:86} INFO - Output:
[2023-06-11T04:48:51.946+0000] {subprocess.py:93} INFO - hey, I am task3 and will be running after task1 at the same time as task2!
[2023-06-11T04:48:51.947+0000] {subprocess.py:97} INFO - Command exited with return code 0
[2023-06-11T04:48:53.994+0000] {taskinstance.py:1350} INFO - Marking task as SUCCESS. dag_id=first_dag_02, task_id=thrid_task, execution_date=20210914T000000, start_date=20230611T044841, end_date=20230611T044853
[2023-06-11T04:48:55.073+0000] {local_task_job_runner.py:225} INFO - Task exited with return code 0
[2023-06-11T04:48:57.557+0000] {taskinstance.py:2651} INFO - 0 downstream tasks scheduled from follow-on schedule check
[2023-06-11T08:25:32.037+0000] {taskinstance.py:1103} INFO - Dependencies all met for dep_context=non-requeueable deps ti=<TaskInstance: first_dag_02.thrid_task scheduled__2021-09-14T00:00:00+00:00 [queued]>
[2023-06-11T08:25:32.388+0000] {taskinstance.py:1103} INFO - Dependencies all met for dep_context=requeueable deps ti=<TaskInstance: first_dag_02.thrid_task scheduled__2021-09-14T00:00:00+00:00 [queued]>
[2023-06-11T08:25:32.399+0000] {taskinstance.py:1308} INFO - Starting attempt 1 of 6
[2023-06-11T08:25:37.103+0000] {taskinstance.py:1327} INFO - Executing <Task(BashOperator): thrid_task> on 2021-09-14 00:00:00+00:00
[2023-06-11T08:25:37.207+0000] {standard_task_runner.py:57} INFO - Started process 1079 to run task
[2023-06-11T08:25:37.492+0000] {standard_task_runner.py:84} INFO - Running: ['***', 'tasks', 'run', 'first_dag_02', 'thrid_task', 'scheduled__2021-09-14T00:00:00+00:00', '--job-id', '335', '--raw', '--subdir', 'DAGS_FOLDER/First_dag.py', '--cfg-path', '/tmp/tmpg08cweyb']
[2023-06-11T08:25:37.494+0000] {standard_task_runner.py:85} INFO - Job 335: Subtask thrid_task
[2023-06-11T08:25:40.300+0000] {task_command.py:410} INFO - Running <TaskInstance: first_dag_02.thrid_task scheduled__2021-09-14T00:00:00+00:00 [running]> on host 492037cdd057
[2023-06-11T08:25:48.060+0000] {taskinstance.py:1547} INFO - Exporting env vars: AIRFLOW_CTX_DAG_OWNER='Raja' AIRFLOW_CTX_DAG_ID='first_dag_02' AIRFLOW_CTX_TASK_ID='thrid_task' AIRFLOW_CTX_EXECUTION_DATE='2021-09-14T00:00:00+00:00' AIRFLOW_CTX_TRY_NUMBER='1' AIRFLOW_CTX_DAG_RUN_ID='scheduled__2021-09-14T00:00:00+00:00'
[2023-06-11T08:25:48.088+0000] {subprocess.py:63} INFO - Tmp dir root location: 
 /tmp
[2023-06-11T08:25:48.089+0000] {subprocess.py:75} INFO - Running command: ['/bin/bash', '-c', 'echo hey, I am task3 and will be running after task1 at the same time as task2!']
[2023-06-11T08:25:48.827+0000] {subprocess.py:86} INFO - Output:
[2023-06-11T08:25:48.861+0000] {subprocess.py:93} INFO - hey, I am task3 and will be running after task1 at the same time as task2!
[2023-06-11T08:25:48.867+0000] {subprocess.py:97} INFO - Command exited with return code 0
[2023-06-11T08:25:50.377+0000] {taskinstance.py:1350} INFO - Marking task as SUCCESS. dag_id=first_dag_02, task_id=thrid_task, execution_date=20210914T000000, start_date=20230611T082532, end_date=20230611T082550
[2023-06-11T08:25:52.066+0000] {local_task_job_runner.py:225} INFO - Task exited with return code 0
[2023-06-11T08:25:52.806+0000] {taskinstance.py:2651} INFO - 0 downstream tasks scheduled from follow-on schedule check
[2023-06-11T08:50:24.239+0000] {taskinstance.py:1103} INFO - Dependencies all met for dep_context=non-requeueable deps ti=<TaskInstance: first_dag_02.thrid_task scheduled__2021-09-14T00:00:00+00:00 [queued]>
[2023-06-11T08:50:24.402+0000] {taskinstance.py:1103} INFO - Dependencies all met for dep_context=requeueable deps ti=<TaskInstance: first_dag_02.thrid_task scheduled__2021-09-14T00:00:00+00:00 [queued]>
[2023-06-11T08:50:24.402+0000] {taskinstance.py:1308} INFO - Starting attempt 1 of 6
[2023-06-11T08:50:24.754+0000] {taskinstance.py:1327} INFO - Executing <Task(BashOperator): thrid_task> on 2021-09-14 00:00:00+00:00
[2023-06-11T08:50:24.769+0000] {standard_task_runner.py:57} INFO - Started process 877 to run task
[2023-06-11T08:50:24.799+0000] {standard_task_runner.py:84} INFO - Running: ['***', 'tasks', 'run', 'first_dag_02', 'thrid_task', 'scheduled__2021-09-14T00:00:00+00:00', '--job-id', '270', '--raw', '--subdir', 'DAGS_FOLDER/First_dag.py', '--cfg-path', '/tmp/tmpyakpgne0']
[2023-06-11T08:50:24.800+0000] {standard_task_runner.py:85} INFO - Job 270: Subtask thrid_task
[2023-06-11T08:50:25.461+0000] {task_command.py:410} INFO - Running <TaskInstance: first_dag_02.thrid_task scheduled__2021-09-14T00:00:00+00:00 [running]> on host 964e508aad03
[2023-06-11T08:50:27.708+0000] {taskinstance.py:1547} INFO - Exporting env vars: AIRFLOW_CTX_DAG_OWNER='Raja' AIRFLOW_CTX_DAG_ID='first_dag_02' AIRFLOW_CTX_TASK_ID='thrid_task' AIRFLOW_CTX_EXECUTION_DATE='2021-09-14T00:00:00+00:00' AIRFLOW_CTX_TRY_NUMBER='1' AIRFLOW_CTX_DAG_RUN_ID='scheduled__2021-09-14T00:00:00+00:00'
[2023-06-11T08:50:27.710+0000] {subprocess.py:63} INFO - Tmp dir root location: 
 /tmp
[2023-06-11T08:50:27.711+0000] {subprocess.py:75} INFO - Running command: ['/bin/bash', '-c', 'echo hey, I am task3 and will be running after task1 at the same time as task2!']
[2023-06-11T08:50:27.749+0000] {subprocess.py:86} INFO - Output:
[2023-06-11T08:50:27.753+0000] {subprocess.py:93} INFO - hey, I am task3 and will be running after task1 at the same time as task2!
[2023-06-11T08:50:27.763+0000] {subprocess.py:97} INFO - Command exited with return code 0
[2023-06-11T08:50:28.140+0000] {taskinstance.py:1350} INFO - Marking task as SUCCESS. dag_id=first_dag_02, task_id=thrid_task, execution_date=20210914T000000, start_date=20230611T085024, end_date=20230611T085028
[2023-06-11T08:50:28.764+0000] {local_task_job_runner.py:225} INFO - Task exited with return code 0
[2023-06-11T08:50:29.470+0000] {taskinstance.py:2651} INFO - 0 downstream tasks scheduled from follow-on schedule check
[2023-06-11T10:48:20.104+0000] {taskinstance.py:1103} INFO - Dependencies all met for dep_context=non-requeueable deps ti=<TaskInstance: first_dag_02.thrid_task scheduled__2021-09-14T00:00:00+00:00 [queued]>
[2023-06-11T10:48:21.106+0000] {taskinstance.py:1103} INFO - Dependencies all met for dep_context=requeueable deps ti=<TaskInstance: first_dag_02.thrid_task scheduled__2021-09-14T00:00:00+00:00 [queued]>
[2023-06-11T10:48:21.107+0000] {taskinstance.py:1308} INFO - Starting attempt 1 of 6
[2023-06-11T10:48:22.459+0000] {taskinstance.py:1327} INFO - Executing <Task(BashOperator): thrid_task> on 2021-09-14 00:00:00+00:00
[2023-06-11T10:48:22.589+0000] {standard_task_runner.py:57} INFO - Started process 930 to run task
[2023-06-11T10:48:22.847+0000] {standard_task_runner.py:84} INFO - Running: ['***', 'tasks', 'run', 'first_dag_02', 'thrid_task', 'scheduled__2021-09-14T00:00:00+00:00', '--job-id', '254', '--raw', '--subdir', 'DAGS_FOLDER/First_dag.py', '--cfg-path', '/tmp/tmp3mgl1_kj']
[2023-06-11T10:48:22.853+0000] {standard_task_runner.py:85} INFO - Job 254: Subtask thrid_task
[2023-06-11T10:52:22.285+0000] {standard_task_runner.py:109} ERROR - Failed to execute job 254 for task thrid_task ((psycopg2.OperationalError) connection to server at "postgres" (172.18.0.3), port 5432 failed: server closed the connection unexpectedly
	This probably means the server terminated abnormally
	before or while processing the request.

(Background on this error at: https://sqlalche.me/e/14/e3q8); 930)
[2023-06-11T10:52:22.333+0000] {job.py:216} ERROR - Job heartbeat got an exception
Traceback (most recent call last):
  File "/home/airflow/.local/lib/python3.7/site-packages/sqlalchemy/engine/base.py", line 3366, in _wrap_pool_connect
    return fn()
  File "/home/airflow/.local/lib/python3.7/site-packages/sqlalchemy/pool/base.py", line 327, in connect
    return _ConnectionFairy._checkout(self)
  File "/home/airflow/.local/lib/python3.7/site-packages/sqlalchemy/pool/base.py", line 894, in _checkout
    fairy = _ConnectionRecord.checkout(pool)
  File "/home/airflow/.local/lib/python3.7/site-packages/sqlalchemy/pool/base.py", line 493, in checkout
    rec = pool._do_get()
  File "/home/airflow/.local/lib/python3.7/site-packages/sqlalchemy/pool/impl.py", line 256, in _do_get
    return self._create_connection()
  File "/home/airflow/.local/lib/python3.7/site-packages/sqlalchemy/pool/base.py", line 273, in _create_connection
    return _ConnectionRecord(self)
  File "/home/airflow/.local/lib/python3.7/site-packages/sqlalchemy/pool/base.py", line 388, in __init__
    self.__connect()
  File "/home/airflow/.local/lib/python3.7/site-packages/sqlalchemy/pool/base.py", line 691, in __connect
    pool.logger.debug("Error on connect(): %s", e)
  File "/home/airflow/.local/lib/python3.7/site-packages/sqlalchemy/util/langhelpers.py", line 72, in __exit__
    with_traceback=exc_tb,
  File "/home/airflow/.local/lib/python3.7/site-packages/sqlalchemy/util/compat.py", line 211, in raise_
    raise exception
  File "/home/airflow/.local/lib/python3.7/site-packages/sqlalchemy/pool/base.py", line 686, in __connect
    self.dbapi_connection = connection = pool._invoke_creator(self)
  File "/home/airflow/.local/lib/python3.7/site-packages/sqlalchemy/engine/create.py", line 574, in connect
    return dialect.connect(*cargs, **cparams)
  File "/home/airflow/.local/lib/python3.7/site-packages/sqlalchemy/engine/default.py", line 598, in connect
    return self.dbapi.connect(*cargs, **cparams)
  File "/home/airflow/.local/lib/python3.7/site-packages/psycopg2/__init__.py", line 122, in connect
    conn = _connect(dsn, connection_factory=connection_factory, **kwasync)
psycopg2.OperationalError: connection to server at "postgres" (172.18.0.3), port 5432 failed: server closed the connection unexpectedly
	This probably means the server terminated abnormally
	before or while processing the request.


The above exception was the direct cause of the following exception:

Traceback (most recent call last):
  File "/home/airflow/.local/lib/python3.7/site-packages/airflow/jobs/job.py", line 187, in heartbeat
    session.merge(self)
  File "/home/airflow/.local/lib/python3.7/site-packages/sqlalchemy/orm/session.py", line 3062, in merge
    _resolve_conflict_map=_resolve_conflict_map,
  File "/home/airflow/.local/lib/python3.7/site-packages/sqlalchemy/orm/session.py", line 3140, in _merge
    options=options,
  File "/home/airflow/.local/lib/python3.7/site-packages/sqlalchemy/orm/session.py", line 2861, in get
    execution_options=execution_options,
  File "/home/airflow/.local/lib/python3.7/site-packages/sqlalchemy/orm/session.py", line 2979, in _get_impl
    load_options=load_options,
  File "/home/airflow/.local/lib/python3.7/site-packages/sqlalchemy/orm/loading.py", line 534, in load_on_pk_identity
    bind_arguments=bind_arguments,
  File "/home/airflow/.local/lib/python3.7/site-packages/sqlalchemy/orm/session.py", line 1716, in execute
    conn = self._connection_for_bind(bind)
  File "/home/airflow/.local/lib/python3.7/site-packages/sqlalchemy/orm/session.py", line 1556, in _connection_for_bind
    engine, execution_options
  File "/home/airflow/.local/lib/python3.7/site-packages/sqlalchemy/orm/session.py", line 750, in _connection_for_bind
    conn = bind.connect()
  File "/home/airflow/.local/lib/python3.7/site-packages/sqlalchemy/engine/base.py", line 3320, in connect
    return self._connection_cls(self, close_with_result=close_with_result)
  File "/home/airflow/.local/lib/python3.7/site-packages/sqlalchemy/engine/base.py", line 96, in __init__
    else engine.raw_connection()
  File "/home/airflow/.local/lib/python3.7/site-packages/sqlalchemy/engine/base.py", line 3399, in raw_connection
    return self._wrap_pool_connect(self.pool.connect, _connection)
  File "/home/airflow/.local/lib/python3.7/site-packages/sqlalchemy/engine/base.py", line 3370, in _wrap_pool_connect
    e, dialect, self
  File "/home/airflow/.local/lib/python3.7/site-packages/sqlalchemy/engine/base.py", line 2204, in _handle_dbapi_exception_noconnection
    sqlalchemy_exception, with_traceback=exc_info[2], from_=e
  File "/home/airflow/.local/lib/python3.7/site-packages/sqlalchemy/util/compat.py", line 211, in raise_
    raise exception
  File "/home/airflow/.local/lib/python3.7/site-packages/sqlalchemy/engine/base.py", line 3366, in _wrap_pool_connect
    return fn()
  File "/home/airflow/.local/lib/python3.7/site-packages/sqlalchemy/pool/base.py", line 327, in connect
    return _ConnectionFairy._checkout(self)
  File "/home/airflow/.local/lib/python3.7/site-packages/sqlalchemy/pool/base.py", line 894, in _checkout
    fairy = _ConnectionRecord.checkout(pool)
  File "/home/airflow/.local/lib/python3.7/site-packages/sqlalchemy/pool/base.py", line 493, in checkout
    rec = pool._do_get()
  File "/home/airflow/.local/lib/python3.7/site-packages/sqlalchemy/pool/impl.py", line 256, in _do_get
    return self._create_connection()
  File "/home/airflow/.local/lib/python3.7/site-packages/sqlalchemy/pool/base.py", line 273, in _create_connection
    return _ConnectionRecord(self)
  File "/home/airflow/.local/lib/python3.7/site-packages/sqlalchemy/pool/base.py", line 388, in __init__
    self.__connect()
  File "/home/airflow/.local/lib/python3.7/site-packages/sqlalchemy/pool/base.py", line 691, in __connect
    pool.logger.debug("Error on connect(): %s", e)
  File "/home/airflow/.local/lib/python3.7/site-packages/sqlalchemy/util/langhelpers.py", line 72, in __exit__
    with_traceback=exc_tb,
  File "/home/airflow/.local/lib/python3.7/site-packages/sqlalchemy/util/compat.py", line 211, in raise_
    raise exception
  File "/home/airflow/.local/lib/python3.7/site-packages/sqlalchemy/pool/base.py", line 686, in __connect
    self.dbapi_connection = connection = pool._invoke_creator(self)
  File "/home/airflow/.local/lib/python3.7/site-packages/sqlalchemy/engine/create.py", line 574, in connect
    return dialect.connect(*cargs, **cparams)
  File "/home/airflow/.local/lib/python3.7/site-packages/sqlalchemy/engine/default.py", line 598, in connect
    return self.dbapi.connect(*cargs, **cparams)
  File "/home/airflow/.local/lib/python3.7/site-packages/psycopg2/__init__.py", line 122, in connect
    conn = _connect(dsn, connection_factory=connection_factory, **kwasync)
sqlalchemy.exc.OperationalError: (psycopg2.OperationalError) connection to server at "postgres" (172.18.0.3), port 5432 failed: server closed the connection unexpectedly
	This probably means the server terminated abnormally
	before or while processing the request.

(Background on this error at: https://sqlalche.me/e/14/e3q8)
[2023-06-11T10:52:25.940+0000] {local_task_job_runner.py:225} INFO - Task exited with return code 1
[2023-06-11T10:52:32.491+0000] {taskinstance.py:2651} INFO - 0 downstream tasks scheduled from follow-on schedule check
