[2023-06-10T16:30:38.827+0000] {taskinstance.py:1103} INFO - Dependencies all met for dep_context=non-requeueable deps ti=<TaskInstance: dag_pythonoperator.second_task scheduled__2023-06-05T00:00:00+00:00 [queued]>
[2023-06-10T16:30:41.265+0000] {taskinstance.py:1103} INFO - Dependencies all met for dep_context=requeueable deps ti=<TaskInstance: dag_pythonoperator.second_task scheduled__2023-06-05T00:00:00+00:00 [queued]>
[2023-06-10T16:30:41.268+0000] {taskinstance.py:1308} INFO - Starting attempt 1 of 6
[2023-06-10T16:30:45.172+0000] {taskinstance.py:1327} INFO - Executing <Task(PythonOperator): second_task> on 2023-06-05 00:00:00+00:00
[2023-06-10T16:30:46.406+0000] {standard_task_runner.py:57} INFO - Started process 4445 to run task
[2023-06-10T16:30:48.919+0000] {standard_task_runner.py:84} INFO - Running: ['***', 'tasks', 'run', 'dag_pythonoperator', 'second_task', 'scheduled__2023-06-05T00:00:00+00:00', '--job-id', '1373', '--raw', '--subdir', 'DAGS_FOLDER/Pythonoperator_dag.py', '--cfg-path', '/tmp/tmp5xeoz3ry']
[2023-06-10T16:30:49.046+0000] {standard_task_runner.py:85} INFO - Job 1373: Subtask second_task
[2023-06-10T16:32:33.091+0000] {cli_action_loggers.py:135} WARNING - Failed to log action (psycopg2.OperationalError) could not translate host name "postgres" to address: Temporary failure in name resolution

(Background on this error at: https://sqlalche.me/e/14/e3q8)
[2023-06-10T16:32:42.518+0000] {task_command.py:410} INFO - Running <TaskInstance: dag_pythonoperator.second_task scheduled__2023-06-05T00:00:00+00:00 [running]> on host e326d5f70fa9
[2023-06-10T16:32:46.847+0000] {taskinstance.py:1547} INFO - Exporting env vars: AIRFLOW_CTX_DAG_OWNER='Raja' AIRFLOW_CTX_DAG_ID='dag_pythonoperator' AIRFLOW_CTX_TASK_ID='second_task' AIRFLOW_CTX_EXECUTION_DATE='2023-06-05T00:00:00+00:00' AIRFLOW_CTX_TRY_NUMBER='1' AIRFLOW_CTX_DAG_RUN_ID='scheduled__2023-06-05T00:00:00+00:00'
[2023-06-10T16:32:46.870+0000] {taskinstance.py:1824} ERROR - Task failed with exception
Traceback (most recent call last):
  File "/home/airflow/.local/lib/python3.7/site-packages/airflow/operators/python.py", line 181, in execute
    return_value = self.execute_callable()
  File "/home/airflow/.local/lib/python3.7/site-packages/airflow/operators/python.py", line 198, in execute_callable
    return self.python_callable(*self.op_args, **self.op_kwargs)
  File "/opt/airflow/dags/Pythonoperator_dag.py", line 16, in retur_values
    first_name=ti.xcom_pull(task_ids=get_name,key='first_name')
  File "/home/airflow/.local/lib/python3.7/site-packages/airflow/utils/session.py", line 76, in wrapper
    return func(*args, session=session, **kwargs)
  File "/home/airflow/.local/lib/python3.7/site-packages/airflow/models/taskinstance.py", line 2441, in xcom_pull
    task_id_whens = {tid: i for i, tid in enumerate(task_ids)}
TypeError: 'function' object is not iterable
[2023-06-10T16:32:47.512+0000] {taskinstance.py:1350} INFO - Marking task as UP_FOR_RETRY. dag_id=dag_pythonoperator, task_id=second_task, execution_date=20230605T000000, start_date=20230610T163039, end_date=20230610T163247
[2023-06-10T16:32:48.087+0000] {standard_task_runner.py:109} ERROR - Failed to execute job 1373 for task second_task ('function' object is not iterable; 4445)
[2023-06-10T16:32:48.343+0000] {local_task_job_runner.py:225} INFO - Task exited with return code 1
[2023-06-10T16:32:49.860+0000] {taskinstance.py:2651} INFO - 0 downstream tasks scheduled from follow-on schedule check
[2023-06-11T04:45:32.318+0000] {taskinstance.py:1103} INFO - Dependencies all met for dep_context=non-requeueable deps ti=<TaskInstance: dag_pythonoperator.second_task scheduled__2023-06-05T00:00:00+00:00 [queued]>
[2023-06-11T04:45:32.502+0000] {taskinstance.py:1103} INFO - Dependencies all met for dep_context=requeueable deps ti=<TaskInstance: dag_pythonoperator.second_task scheduled__2023-06-05T00:00:00+00:00 [queued]>
[2023-06-11T04:45:32.503+0000] {taskinstance.py:1308} INFO - Starting attempt 1 of 6
[2023-06-11T04:45:32.832+0000] {taskinstance.py:1327} INFO - Executing <Task(PythonOperator): second_task> on 2023-06-05 00:00:00+00:00
[2023-06-11T04:45:32.879+0000] {standard_task_runner.py:84} INFO - Running: ['***', 'tasks', 'run', 'dag_pythonoperator', 'second_task', 'scheduled__2023-06-05T00:00:00+00:00', '--job-id', '74', '--raw', '--subdir', 'DAGS_FOLDER/python_operator_dag.py', '--cfg-path', '/tmp/tmp4g9itaod']
[2023-06-11T04:45:32.856+0000] {standard_task_runner.py:57} INFO - Started process 284 to run task
[2023-06-11T04:45:32.934+0000] {standard_task_runner.py:85} INFO - Job 74: Subtask second_task
[2023-06-11T04:45:34.033+0000] {task_command.py:410} INFO - Running <TaskInstance: dag_pythonoperator.second_task scheduled__2023-06-05T00:00:00+00:00 [running]> on host 4b1b5d40d165
[2023-06-11T04:45:37.754+0000] {taskinstance.py:1547} INFO - Exporting env vars: AIRFLOW_CTX_DAG_OWNER='Raja' AIRFLOW_CTX_DAG_ID='dag_pythonoperator' AIRFLOW_CTX_TASK_ID='second_task' AIRFLOW_CTX_EXECUTION_DATE='2023-06-05T00:00:00+00:00' AIRFLOW_CTX_TRY_NUMBER='1' AIRFLOW_CTX_DAG_RUN_ID='scheduled__2023-06-05T00:00:00+00:00'
[2023-06-11T04:45:37.781+0000] {taskinstance.py:1824} ERROR - Task failed with exception
Traceback (most recent call last):
  File "/home/airflow/.local/lib/python3.7/site-packages/airflow/operators/python.py", line 181, in execute
    return_value = self.execute_callable()
  File "/home/airflow/.local/lib/python3.7/site-packages/airflow/operators/python.py", line 198, in execute_callable
    return self.python_callable(*self.op_args, **self.op_kwargs)
  File "/opt/airflow/dags/python_operator_dag.py", line 16, in retur_values
    first_name=ti.xcom_pull(task_ids=get_name,key='first_name')
  File "/home/airflow/.local/lib/python3.7/site-packages/airflow/utils/session.py", line 76, in wrapper
    return func(*args, session=session, **kwargs)
  File "/home/airflow/.local/lib/python3.7/site-packages/airflow/models/taskinstance.py", line 2441, in xcom_pull
    task_id_whens = {tid: i for i, tid in enumerate(task_ids)}
TypeError: 'function' object is not iterable
[2023-06-11T04:45:38.094+0000] {taskinstance.py:1350} INFO - Marking task as UP_FOR_RETRY. dag_id=dag_pythonoperator, task_id=second_task, execution_date=20230605T000000, start_date=20230611T044532, end_date=20230611T044538
[2023-06-11T04:45:38.503+0000] {standard_task_runner.py:109} ERROR - Failed to execute job 74 for task second_task ('function' object is not iterable; 284)
[2023-06-11T04:45:38.660+0000] {local_task_job_runner.py:225} INFO - Task exited with return code 1
[2023-06-11T04:45:38.810+0000] {taskinstance.py:2651} INFO - 0 downstream tasks scheduled from follow-on schedule check
