[2023-06-12T07:14:35.112+0000] {taskinstance.py:1103} INFO - Dependencies all met for dep_context=non-requeueable deps ti=<TaskInstance: s3_upload_dag_18.upload_to_s3 manual__2023-06-12T07:14:31.406203+00:00 [queued]>
[2023-06-12T07:14:35.180+0000] {taskinstance.py:1103} INFO - Dependencies all met for dep_context=requeueable deps ti=<TaskInstance: s3_upload_dag_18.upload_to_s3 manual__2023-06-12T07:14:31.406203+00:00 [queued]>
[2023-06-12T07:14:35.181+0000] {taskinstance.py:1308} INFO - Starting attempt 1 of 2
[2023-06-12T07:14:35.225+0000] {taskinstance.py:1327} INFO - Executing <Task(PythonOperator): upload_to_s3> on 2023-06-12 07:14:31.406203+00:00
[2023-06-12T07:14:35.248+0000] {standard_task_runner.py:57} INFO - Started process 737 to run task
[2023-06-12T07:14:35.257+0000] {standard_task_runner.py:84} INFO - Running: ['***', 'tasks', 'run', 's3_upload_dag_18', 'upload_to_s3', 'manual__2023-06-12T07:14:31.406203+00:00', '--job-id', '285', '--raw', '--subdir', 'DAGS_FOLDER/s3_dag.py', '--cfg-path', '/tmp/tmp53_tysdv']
[2023-06-12T07:14:35.258+0000] {standard_task_runner.py:85} INFO - Job 285: Subtask upload_to_s3
[2023-06-12T07:14:35.354+0000] {task_command.py:410} INFO - Running <TaskInstance: s3_upload_dag_18.upload_to_s3 manual__2023-06-12T07:14:31.406203+00:00 [running]> on host 03cd9a7904e9
[2023-06-12T07:14:35.592+0000] {taskinstance.py:1547} INFO - Exporting env vars: AIRFLOW_CTX_DAG_OWNER='Raja' AIRFLOW_CTX_DAG_ID='s3_upload_dag_18' AIRFLOW_CTX_TASK_ID='upload_to_s3' AIRFLOW_CTX_EXECUTION_DATE='2023-06-12T07:14:31.406203+00:00' AIRFLOW_CTX_TRY_NUMBER='1' AIRFLOW_CTX_DAG_RUN_ID='manual__2023-06-12T07:14:31.406203+00:00'
[2023-06-12T07:14:35.608+0000] {base.py:73} INFO - Using connection ID 'S3_conn' for task execution.
[2023-06-12T07:14:35.609+0000] {connection_wrapper.py:337} INFO - AWS Connection (conn_id='S3_conn', conn_type='aws') credentials retrieved from login and password.
[2023-06-12T07:14:46.993+0000] {taskinstance.py:1824} ERROR - Task failed with exception
Traceback (most recent call last):
  File "/home/airflow/.local/lib/python3.7/site-packages/airflow/operators/python.py", line 181, in execute
    return_value = self.execute_callable()
  File "/home/airflow/.local/lib/python3.7/site-packages/airflow/operators/python.py", line 198, in execute_callable
    return self.python_callable(*self.op_args, **self.op_kwargs)
  File "/opt/airflow/dags/s3_dag.py", line 20, in upload_to_s3
    hook.load_file(filename=filename, key=key, bucket_name=bucket_name)
  File "/home/airflow/.local/lib/python3.7/site-packages/airflow/providers/amazon/aws/hooks/s3.py", line 111, in wrapper
    return func(*bound_args.args, **bound_args.kwargs)
  File "/home/airflow/.local/lib/python3.7/site-packages/airflow/providers/amazon/aws/hooks/s3.py", line 82, in wrapper
    return func(*bound_args.args, **bound_args.kwargs)
  File "/home/airflow/.local/lib/python3.7/site-packages/airflow/providers/amazon/aws/hooks/s3.py", line 677, in load_file
    raise ValueError(f"The key {key} already exists.")
ValueError: The key test.txt already exists.
[2023-06-12T07:14:47.037+0000] {taskinstance.py:1350} INFO - Marking task as UP_FOR_RETRY. dag_id=s3_upload_dag_18, task_id=upload_to_s3, execution_date=20230612T071431, start_date=20230612T071435, end_date=20230612T071447
[2023-06-12T07:14:47.077+0000] {standard_task_runner.py:109} ERROR - Failed to execute job 285 for task upload_to_s3 (The key test.txt already exists.; 737)
[2023-06-12T07:14:47.127+0000] {local_task_job_runner.py:225} INFO - Task exited with return code 1
[2023-06-12T07:14:47.179+0000] {taskinstance.py:2651} INFO - 0 downstream tasks scheduled from follow-on schedule check
