[2023-06-10T16:30:28.210+0000] {taskinstance.py:1103} INFO - Dependencies all met for dep_context=non-requeueable deps ti=<TaskInstance: dag_pythonoperator.second_task scheduled__2023-06-04T00:00:00+00:00 [queued]>
[2023-06-10T16:30:34.723+0000] {taskinstance.py:1103} INFO - Dependencies all met for dep_context=requeueable deps ti=<TaskInstance: dag_pythonoperator.second_task scheduled__2023-06-04T00:00:00+00:00 [queued]>
[2023-06-10T16:30:34.785+0000] {taskinstance.py:1308} INFO - Starting attempt 1 of 6
[2023-06-10T16:30:44.197+0000] {taskinstance.py:1327} INFO - Executing <Task(PythonOperator): second_task> on 2023-06-04 00:00:00+00:00
[2023-06-10T16:30:45.187+0000] {standard_task_runner.py:57} INFO - Started process 4444 to run task
[2023-06-10T16:30:47.153+0000] {standard_task_runner.py:84} INFO - Running: ['***', 'tasks', 'run', 'dag_pythonoperator', 'second_task', 'scheduled__2023-06-04T00:00:00+00:00', '--job-id', '1372', '--raw', '--subdir', 'DAGS_FOLDER/Pythonoperator_dag.py', '--cfg-path', '/tmp/tmp7oh613zl']
[2023-06-10T16:30:47.614+0000] {standard_task_runner.py:85} INFO - Job 1372: Subtask second_task
[2023-06-10T16:31:08.782+0000] {cli_action_loggers.py:135} WARNING - Failed to log action (psycopg2.OperationalError) could not translate host name "postgres" to address: Temporary failure in name resolution

(Background on this error at: https://sqlalche.me/e/14/e3q8)
[2023-06-10T16:32:33.073+0000] {job.py:216} ERROR - Job heartbeat got an exception
Traceback (most recent call last):
  File "/home/airflow/.local/lib/python3.7/site-packages/sqlalchemy/engine/base.py", line 3366, in _wrap_pool_connect
    return fn()
  File "/home/airflow/.local/lib/python3.7/site-packages/sqlalchemy/pool/base.py", line 327, in connect
    return _ConnectionFairy._checkout(self)
  File "/home/airflow/.local/lib/python3.7/site-packages/sqlalchemy/pool/base.py", line 894, in _checkout
    fairy = _ConnectionRecord.checkout(pool)
  File "/home/airflow/.local/lib/python3.7/site-packages/sqlalchemy/pool/base.py", line 493, in checkout
    rec = pool._do_get()
  File "/home/airflow/.local/lib/python3.7/site-packages/sqlalchemy/pool/impl.py", line 256, in _do_get
    return self._create_connection()
  File "/home/airflow/.local/lib/python3.7/site-packages/sqlalchemy/pool/base.py", line 273, in _create_connection
    return _ConnectionRecord(self)
  File "/home/airflow/.local/lib/python3.7/site-packages/sqlalchemy/pool/base.py", line 388, in __init__
    self.__connect()
  File "/home/airflow/.local/lib/python3.7/site-packages/sqlalchemy/pool/base.py", line 691, in __connect
    pool.logger.debug("Error on connect(): %s", e)
  File "/home/airflow/.local/lib/python3.7/site-packages/sqlalchemy/util/langhelpers.py", line 72, in __exit__
    with_traceback=exc_tb,
  File "/home/airflow/.local/lib/python3.7/site-packages/sqlalchemy/util/compat.py", line 211, in raise_
    raise exception
  File "/home/airflow/.local/lib/python3.7/site-packages/sqlalchemy/pool/base.py", line 686, in __connect
    self.dbapi_connection = connection = pool._invoke_creator(self)
  File "/home/airflow/.local/lib/python3.7/site-packages/sqlalchemy/engine/create.py", line 574, in connect
    return dialect.connect(*cargs, **cparams)
  File "/home/airflow/.local/lib/python3.7/site-packages/sqlalchemy/engine/default.py", line 598, in connect
    return self.dbapi.connect(*cargs, **cparams)
  File "/home/airflow/.local/lib/python3.7/site-packages/psycopg2/__init__.py", line 122, in connect
    conn = _connect(dsn, connection_factory=connection_factory, **kwasync)
psycopg2.OperationalError: could not translate host name "postgres" to address: Temporary failure in name resolution


The above exception was the direct cause of the following exception:

Traceback (most recent call last):
  File "/home/airflow/.local/lib/python3.7/site-packages/airflow/jobs/job.py", line 187, in heartbeat
    session.merge(self)
  File "/home/airflow/.local/lib/python3.7/site-packages/sqlalchemy/orm/session.py", line 3062, in merge
    _resolve_conflict_map=_resolve_conflict_map,
  File "/home/airflow/.local/lib/python3.7/site-packages/sqlalchemy/orm/session.py", line 3140, in _merge
    options=options,
  File "/home/airflow/.local/lib/python3.7/site-packages/sqlalchemy/orm/session.py", line 2861, in get
    execution_options=execution_options,
  File "/home/airflow/.local/lib/python3.7/site-packages/sqlalchemy/orm/session.py", line 2979, in _get_impl
    load_options=load_options,
  File "/home/airflow/.local/lib/python3.7/site-packages/sqlalchemy/orm/loading.py", line 534, in load_on_pk_identity
    bind_arguments=bind_arguments,
  File "/home/airflow/.local/lib/python3.7/site-packages/sqlalchemy/orm/session.py", line 1716, in execute
    conn = self._connection_for_bind(bind)
  File "/home/airflow/.local/lib/python3.7/site-packages/sqlalchemy/orm/session.py", line 1556, in _connection_for_bind
    engine, execution_options
  File "/home/airflow/.local/lib/python3.7/site-packages/sqlalchemy/orm/session.py", line 750, in _connection_for_bind
    conn = bind.connect()
  File "/home/airflow/.local/lib/python3.7/site-packages/sqlalchemy/engine/base.py", line 3320, in connect
    return self._connection_cls(self, close_with_result=close_with_result)
  File "/home/airflow/.local/lib/python3.7/site-packages/sqlalchemy/engine/base.py", line 96, in __init__
    else engine.raw_connection()
  File "/home/airflow/.local/lib/python3.7/site-packages/sqlalchemy/engine/base.py", line 3399, in raw_connection
    return self._wrap_pool_connect(self.pool.connect, _connection)
  File "/home/airflow/.local/lib/python3.7/site-packages/sqlalchemy/engine/base.py", line 3370, in _wrap_pool_connect
    e, dialect, self
  File "/home/airflow/.local/lib/python3.7/site-packages/sqlalchemy/engine/base.py", line 2204, in _handle_dbapi_exception_noconnection
    sqlalchemy_exception, with_traceback=exc_info[2], from_=e
  File "/home/airflow/.local/lib/python3.7/site-packages/sqlalchemy/util/compat.py", line 211, in raise_
    raise exception
  File "/home/airflow/.local/lib/python3.7/site-packages/sqlalchemy/engine/base.py", line 3366, in _wrap_pool_connect
    return fn()
  File "/home/airflow/.local/lib/python3.7/site-packages/sqlalchemy/pool/base.py", line 327, in connect
    return _ConnectionFairy._checkout(self)
  File "/home/airflow/.local/lib/python3.7/site-packages/sqlalchemy/pool/base.py", line 894, in _checkout
    fairy = _ConnectionRecord.checkout(pool)
  File "/home/airflow/.local/lib/python3.7/site-packages/sqlalchemy/pool/base.py", line 493, in checkout
    rec = pool._do_get()
  File "/home/airflow/.local/lib/python3.7/site-packages/sqlalchemy/pool/impl.py", line 256, in _do_get
    return self._create_connection()
  File "/home/airflow/.local/lib/python3.7/site-packages/sqlalchemy/pool/base.py", line 273, in _create_connection
    return _ConnectionRecord(self)
  File "/home/airflow/.local/lib/python3.7/site-packages/sqlalchemy/pool/base.py", line 388, in __init__
    self.__connect()
  File "/home/airflow/.local/lib/python3.7/site-packages/sqlalchemy/pool/base.py", line 691, in __connect
    pool.logger.debug("Error on connect(): %s", e)
  File "/home/airflow/.local/lib/python3.7/site-packages/sqlalchemy/util/langhelpers.py", line 72, in __exit__
    with_traceback=exc_tb,
  File "/home/airflow/.local/lib/python3.7/site-packages/sqlalchemy/util/compat.py", line 211, in raise_
    raise exception
  File "/home/airflow/.local/lib/python3.7/site-packages/sqlalchemy/pool/base.py", line 686, in __connect
    self.dbapi_connection = connection = pool._invoke_creator(self)
  File "/home/airflow/.local/lib/python3.7/site-packages/sqlalchemy/engine/create.py", line 574, in connect
    return dialect.connect(*cargs, **cparams)
  File "/home/airflow/.local/lib/python3.7/site-packages/sqlalchemy/engine/default.py", line 598, in connect
    return self.dbapi.connect(*cargs, **cparams)
  File "/home/airflow/.local/lib/python3.7/site-packages/psycopg2/__init__.py", line 122, in connect
    conn = _connect(dsn, connection_factory=connection_factory, **kwasync)
sqlalchemy.exc.OperationalError: (psycopg2.OperationalError) could not translate host name "postgres" to address: Temporary failure in name resolution

(Background on this error at: https://sqlalche.me/e/14/e3q8)
[2023-06-10T16:32:42.041+0000] {task_command.py:410} INFO - Running <TaskInstance: dag_pythonoperator.second_task scheduled__2023-06-04T00:00:00+00:00 [running]> on host e326d5f70fa9
[2023-06-10T16:32:48.072+0000] {taskinstance.py:1547} INFO - Exporting env vars: AIRFLOW_CTX_DAG_OWNER='Raja' AIRFLOW_CTX_DAG_ID='dag_pythonoperator' AIRFLOW_CTX_TASK_ID='second_task' AIRFLOW_CTX_EXECUTION_DATE='2023-06-04T00:00:00+00:00' AIRFLOW_CTX_TRY_NUMBER='1' AIRFLOW_CTX_DAG_RUN_ID='scheduled__2023-06-04T00:00:00+00:00'
[2023-06-10T16:32:48.401+0000] {taskinstance.py:1824} ERROR - Task failed with exception
Traceback (most recent call last):
  File "/home/airflow/.local/lib/python3.7/site-packages/airflow/operators/python.py", line 181, in execute
    return_value = self.execute_callable()
  File "/home/airflow/.local/lib/python3.7/site-packages/airflow/operators/python.py", line 198, in execute_callable
    return self.python_callable(*self.op_args, **self.op_kwargs)
  File "/opt/airflow/dags/Pythonoperator_dag.py", line 16, in retur_values
    first_name=ti.xcom_pull(task_ids=get_name,key='first_name')
  File "/home/airflow/.local/lib/python3.7/site-packages/airflow/utils/session.py", line 76, in wrapper
    return func(*args, session=session, **kwargs)
  File "/home/airflow/.local/lib/python3.7/site-packages/airflow/models/taskinstance.py", line 2441, in xcom_pull
    task_id_whens = {tid: i for i, tid in enumerate(task_ids)}
TypeError: 'function' object is not iterable
[2023-06-10T16:32:48.603+0000] {taskinstance.py:1350} INFO - Marking task as UP_FOR_RETRY. dag_id=dag_pythonoperator, task_id=second_task, execution_date=20230604T000000, start_date=20230610T163030, end_date=20230610T163248
[2023-06-10T16:32:48.771+0000] {standard_task_runner.py:109} ERROR - Failed to execute job 1372 for task second_task ('function' object is not iterable; 4444)
[2023-06-10T16:32:48.838+0000] {local_task_job_runner.py:225} INFO - Task exited with return code 1
[2023-06-10T16:32:50.135+0000] {taskinstance.py:2651} INFO - 0 downstream tasks scheduled from follow-on schedule check
[2023-06-11T04:45:32.621+0000] {taskinstance.py:1103} INFO - Dependencies all met for dep_context=non-requeueable deps ti=<TaskInstance: dag_pythonoperator.second_task scheduled__2023-06-04T00:00:00+00:00 [queued]>
[2023-06-11T04:45:32.771+0000] {taskinstance.py:1103} INFO - Dependencies all met for dep_context=requeueable deps ti=<TaskInstance: dag_pythonoperator.second_task scheduled__2023-06-04T00:00:00+00:00 [queued]>
[2023-06-11T04:45:32.780+0000] {taskinstance.py:1308} INFO - Starting attempt 1 of 6
[2023-06-11T04:45:33.045+0000] {taskinstance.py:1327} INFO - Executing <Task(PythonOperator): second_task> on 2023-06-04 00:00:00+00:00
[2023-06-11T04:45:33.053+0000] {standard_task_runner.py:57} INFO - Started process 287 to run task
[2023-06-11T04:45:33.062+0000] {standard_task_runner.py:84} INFO - Running: ['***', 'tasks', 'run', 'dag_pythonoperator', 'second_task', 'scheduled__2023-06-04T00:00:00+00:00', '--job-id', '76', '--raw', '--subdir', 'DAGS_FOLDER/python_operator_dag.py', '--cfg-path', '/tmp/tmp01q7k8vz']
[2023-06-11T04:45:33.062+0000] {standard_task_runner.py:85} INFO - Job 76: Subtask second_task
[2023-06-11T04:45:33.218+0000] {task_command.py:410} INFO - Running <TaskInstance: dag_pythonoperator.second_task scheduled__2023-06-04T00:00:00+00:00 [running]> on host 4b1b5d40d165
[2023-06-11T04:45:35.758+0000] {taskinstance.py:1547} INFO - Exporting env vars: AIRFLOW_CTX_DAG_OWNER='Raja' AIRFLOW_CTX_DAG_ID='dag_pythonoperator' AIRFLOW_CTX_TASK_ID='second_task' AIRFLOW_CTX_EXECUTION_DATE='2023-06-04T00:00:00+00:00' AIRFLOW_CTX_TRY_NUMBER='1' AIRFLOW_CTX_DAG_RUN_ID='scheduled__2023-06-04T00:00:00+00:00'
[2023-06-11T04:45:35.915+0000] {taskinstance.py:1824} ERROR - Task failed with exception
Traceback (most recent call last):
  File "/home/airflow/.local/lib/python3.7/site-packages/airflow/operators/python.py", line 181, in execute
    return_value = self.execute_callable()
  File "/home/airflow/.local/lib/python3.7/site-packages/airflow/operators/python.py", line 198, in execute_callable
    return self.python_callable(*self.op_args, **self.op_kwargs)
  File "/opt/airflow/dags/python_operator_dag.py", line 16, in retur_values
    first_name=ti.xcom_pull(task_ids=get_name,key='first_name')
  File "/home/airflow/.local/lib/python3.7/site-packages/airflow/utils/session.py", line 76, in wrapper
    return func(*args, session=session, **kwargs)
  File "/home/airflow/.local/lib/python3.7/site-packages/airflow/models/taskinstance.py", line 2441, in xcom_pull
    task_id_whens = {tid: i for i, tid in enumerate(task_ids)}
TypeError: 'function' object is not iterable
[2023-06-11T04:45:36.000+0000] {taskinstance.py:1350} INFO - Marking task as UP_FOR_RETRY. dag_id=dag_pythonoperator, task_id=second_task, execution_date=20230604T000000, start_date=20230611T044532, end_date=20230611T044535
[2023-06-11T04:45:36.072+0000] {standard_task_runner.py:109} ERROR - Failed to execute job 76 for task second_task ('function' object is not iterable; 287)
[2023-06-11T04:45:36.148+0000] {local_task_job_runner.py:225} INFO - Task exited with return code 1
[2023-06-11T04:45:36.471+0000] {taskinstance.py:2651} INFO - 0 downstream tasks scheduled from follow-on schedule check
