[2023-06-10T17:29:22.605+0000] {taskinstance.py:1103} INFO - Dependencies all met for dep_context=non-requeueable deps ti=<TaskInstance: first_dag_02.second_task scheduled__2021-08-15T00:00:00+00:00 [queued]>
[2023-06-10T17:29:23.573+0000] {taskinstance.py:1103} INFO - Dependencies all met for dep_context=requeueable deps ti=<TaskInstance: first_dag_02.second_task scheduled__2021-08-15T00:00:00+00:00 [queued]>
[2023-06-10T17:29:23.573+0000] {taskinstance.py:1308} INFO - Starting attempt 1 of 6
[2023-06-10T17:29:24.477+0000] {taskinstance.py:1327} INFO - Executing <Task(BashOperator): second_task> on 2021-08-15 00:00:00+00:00
[2023-06-10T17:29:24.500+0000] {standard_task_runner.py:57} INFO - Started process 1069 to run task
[2023-06-10T17:29:24.748+0000] {standard_task_runner.py:84} INFO - Running: ['***', 'tasks', 'run', 'first_dag_02', 'second_task', 'scheduled__2021-08-15T00:00:00+00:00', '--job-id', '1855', '--raw', '--subdir', 'DAGS_FOLDER/First_dag.py', '--cfg-path', '/tmp/tmps2zvo0fx']
[2023-06-10T17:29:24.771+0000] {standard_task_runner.py:85} INFO - Job 1855: Subtask second_task
[2023-06-10T17:29:27.188+0000] {task_command.py:410} INFO - Running <TaskInstance: first_dag_02.second_task scheduled__2021-08-15T00:00:00+00:00 [running]> on host e326d5f70fa9
[2023-06-10T17:30:00.380+0000] {taskinstance.py:1547} INFO - Exporting env vars: AIRFLOW_CTX_DAG_OWNER='Raja' AIRFLOW_CTX_DAG_ID='first_dag_02' AIRFLOW_CTX_TASK_ID='second_task' AIRFLOW_CTX_EXECUTION_DATE='2021-08-15T00:00:00+00:00' AIRFLOW_CTX_TRY_NUMBER='1' AIRFLOW_CTX_DAG_RUN_ID='scheduled__2021-08-15T00:00:00+00:00'
[2023-06-10T17:30:05.248+0000] {subprocess.py:63} INFO - Tmp dir root location: 
 /tmp
[2023-06-10T17:30:05.416+0000] {subprocess.py:75} INFO - Running command: ['/bin/bash', '-c', 'echo hey, I am task2 and will be running after task1!']
[2023-06-10T17:30:07.163+0000] {subprocess.py:86} INFO - Output:
[2023-06-10T17:30:09.124+0000] {subprocess.py:93} INFO - hey, I am task2 and will be running after task1!
[2023-06-10T17:30:09.135+0000] {subprocess.py:97} INFO - Command exited with return code 0
[2023-06-10T17:30:13.753+0000] {taskinstance.py:1824} ERROR - Task failed with exception
Traceback (most recent call last):
  File "/home/airflow/.local/lib/python3.7/site-packages/sqlalchemy/engine/base.py", line 3366, in _wrap_pool_connect
    return fn()
  File "/home/airflow/.local/lib/python3.7/site-packages/sqlalchemy/pool/base.py", line 327, in connect
    return _ConnectionFairy._checkout(self)
  File "/home/airflow/.local/lib/python3.7/site-packages/sqlalchemy/pool/base.py", line 894, in _checkout
    fairy = _ConnectionRecord.checkout(pool)
  File "/home/airflow/.local/lib/python3.7/site-packages/sqlalchemy/pool/base.py", line 493, in checkout
    rec = pool._do_get()
  File "/home/airflow/.local/lib/python3.7/site-packages/sqlalchemy/pool/impl.py", line 256, in _do_get
    return self._create_connection()
  File "/home/airflow/.local/lib/python3.7/site-packages/sqlalchemy/pool/base.py", line 273, in _create_connection
    return _ConnectionRecord(self)
  File "/home/airflow/.local/lib/python3.7/site-packages/sqlalchemy/pool/base.py", line 388, in __init__
    self.__connect()
  File "/home/airflow/.local/lib/python3.7/site-packages/sqlalchemy/pool/base.py", line 691, in __connect
    pool.logger.debug("Error on connect(): %s", e)
  File "/home/airflow/.local/lib/python3.7/site-packages/sqlalchemy/util/langhelpers.py", line 72, in __exit__
    with_traceback=exc_tb,
  File "/home/airflow/.local/lib/python3.7/site-packages/sqlalchemy/util/compat.py", line 211, in raise_
    raise exception
  File "/home/airflow/.local/lib/python3.7/site-packages/sqlalchemy/pool/base.py", line 686, in __connect
    self.dbapi_connection = connection = pool._invoke_creator(self)
  File "/home/airflow/.local/lib/python3.7/site-packages/sqlalchemy/engine/create.py", line 574, in connect
    return dialect.connect(*cargs, **cparams)
  File "/home/airflow/.local/lib/python3.7/site-packages/sqlalchemy/engine/default.py", line 598, in connect
    return self.dbapi.connect(*cargs, **cparams)
  File "/home/airflow/.local/lib/python3.7/site-packages/psycopg2/__init__.py", line 122, in connect
    conn = _connect(dsn, connection_factory=connection_factory, **kwasync)
psycopg2.OperationalError: could not translate host name "postgres" to address: Temporary failure in name resolution


The above exception was the direct cause of the following exception:

Traceback (most recent call last):
  File "/home/airflow/.local/lib/python3.7/site-packages/airflow/models/taskinstance.py", line 1409, in _run_raw_task
    self.refresh_from_db(lock_for_update=True, session=session)
  File "/home/airflow/.local/lib/python3.7/site-packages/airflow/utils/session.py", line 73, in wrapper
    return func(*args, **kwargs)
  File "/home/airflow/.local/lib/python3.7/site-packages/airflow/models/taskinstance.py", line 807, in refresh_from_db
    for attempt in run_with_db_retries(logger=self.log):
  File "/home/airflow/.local/lib/python3.7/site-packages/tenacity/__init__.py", line 347, in __iter__
    do = self.iter(retry_state=retry_state)
  File "/home/airflow/.local/lib/python3.7/site-packages/tenacity/__init__.py", line 325, in iter
    raise retry_exc.reraise()
  File "/home/airflow/.local/lib/python3.7/site-packages/tenacity/__init__.py", line 158, in reraise
    raise self.last_attempt.result()
  File "/usr/local/lib/python3.7/concurrent/futures/_base.py", line 428, in result
    return self.__get_result()
  File "/usr/local/lib/python3.7/concurrent/futures/_base.py", line 384, in __get_result
    raise self._exception
  File "/home/airflow/.local/lib/python3.7/site-packages/airflow/models/taskinstance.py", line 809, in refresh_from_db
    ti: TaskInstance | None = qry.with_for_update().one_or_none()
  File "/home/airflow/.local/lib/python3.7/site-packages/sqlalchemy/orm/query.py", line 2850, in one_or_none
    return self._iter().one_or_none()
  File "/home/airflow/.local/lib/python3.7/site-packages/sqlalchemy/orm/query.py", line 2919, in _iter
    execution_options={"_sa_orm_load_options": self.load_options},
  File "/home/airflow/.local/lib/python3.7/site-packages/sqlalchemy/orm/session.py", line 1716, in execute
    conn = self._connection_for_bind(bind)
  File "/home/airflow/.local/lib/python3.7/site-packages/sqlalchemy/orm/session.py", line 1556, in _connection_for_bind
    engine, execution_options
  File "/home/airflow/.local/lib/python3.7/site-packages/sqlalchemy/orm/session.py", line 750, in _connection_for_bind
    conn = bind.connect()
  File "/home/airflow/.local/lib/python3.7/site-packages/sqlalchemy/engine/base.py", line 3320, in connect
    return self._connection_cls(self, close_with_result=close_with_result)
  File "/home/airflow/.local/lib/python3.7/site-packages/sqlalchemy/engine/base.py", line 96, in __init__
    else engine.raw_connection()
  File "/home/airflow/.local/lib/python3.7/site-packages/sqlalchemy/engine/base.py", line 3399, in raw_connection
    return self._wrap_pool_connect(self.pool.connect, _connection)
  File "/home/airflow/.local/lib/python3.7/site-packages/sqlalchemy/engine/base.py", line 3370, in _wrap_pool_connect
    e, dialect, self
  File "/home/airflow/.local/lib/python3.7/site-packages/sqlalchemy/engine/base.py", line 2204, in _handle_dbapi_exception_noconnection
    sqlalchemy_exception, with_traceback=exc_info[2], from_=e
  File "/home/airflow/.local/lib/python3.7/site-packages/sqlalchemy/util/compat.py", line 211, in raise_
    raise exception
  File "/home/airflow/.local/lib/python3.7/site-packages/sqlalchemy/engine/base.py", line 3366, in _wrap_pool_connect
    return fn()
  File "/home/airflow/.local/lib/python3.7/site-packages/sqlalchemy/pool/base.py", line 327, in connect
    return _ConnectionFairy._checkout(self)
  File "/home/airflow/.local/lib/python3.7/site-packages/sqlalchemy/pool/base.py", line 894, in _checkout
    fairy = _ConnectionRecord.checkout(pool)
  File "/home/airflow/.local/lib/python3.7/site-packages/sqlalchemy/pool/base.py", line 493, in checkout
    rec = pool._do_get()
  File "/home/airflow/.local/lib/python3.7/site-packages/sqlalchemy/pool/impl.py", line 256, in _do_get
    return self._create_connection()
  File "/home/airflow/.local/lib/python3.7/site-packages/sqlalchemy/pool/base.py", line 273, in _create_connection
    return _ConnectionRecord(self)
  File "/home/airflow/.local/lib/python3.7/site-packages/sqlalchemy/pool/base.py", line 388, in __init__
    self.__connect()
  File "/home/airflow/.local/lib/python3.7/site-packages/sqlalchemy/pool/base.py", line 691, in __connect
    pool.logger.debug("Error on connect(): %s", e)
  File "/home/airflow/.local/lib/python3.7/site-packages/sqlalchemy/util/langhelpers.py", line 72, in __exit__
    with_traceback=exc_tb,
  File "/home/airflow/.local/lib/python3.7/site-packages/sqlalchemy/util/compat.py", line 211, in raise_
    raise exception
  File "/home/airflow/.local/lib/python3.7/site-packages/sqlalchemy/pool/base.py", line 686, in __connect
    self.dbapi_connection = connection = pool._invoke_creator(self)
  File "/home/airflow/.local/lib/python3.7/site-packages/sqlalchemy/engine/create.py", line 574, in connect
    return dialect.connect(*cargs, **cparams)
  File "/home/airflow/.local/lib/python3.7/site-packages/sqlalchemy/engine/default.py", line 598, in connect
    return self.dbapi.connect(*cargs, **cparams)
  File "/home/airflow/.local/lib/python3.7/site-packages/psycopg2/__init__.py", line 122, in connect
    conn = _connect(dsn, connection_factory=connection_factory, **kwasync)
sqlalchemy.exc.OperationalError: (psycopg2.OperationalError) could not translate host name "postgres" to address: Temporary failure in name resolution

(Background on this error at: https://sqlalche.me/e/14/e3q8)
[2023-06-10T17:30:14.024+0000] {standard_task_runner.py:109} ERROR - Failed to execute job 1855 for task second_task ((psycopg2.OperationalError) could not translate host name "postgres" to address: Temporary failure in name resolution

(Background on this error at: https://sqlalche.me/e/14/e3q8); 1069)
[2023-06-10T17:30:14.230+0000] {local_task_job_runner.py:225} INFO - Task exited with return code 1
[2023-06-10T17:30:14.253+0000] {taskinstance.py:2660} INFO - Skipping mini scheduling run due to exception: None
Traceback (most recent call last):
  File "/home/airflow/.local/lib/python3.7/site-packages/sqlalchemy/engine/base.py", line 3366, in _wrap_pool_connect
    return fn()
  File "/home/airflow/.local/lib/python3.7/site-packages/sqlalchemy/pool/base.py", line 327, in connect
    return _ConnectionFairy._checkout(self)
  File "/home/airflow/.local/lib/python3.7/site-packages/sqlalchemy/pool/base.py", line 894, in _checkout
    fairy = _ConnectionRecord.checkout(pool)
  File "/home/airflow/.local/lib/python3.7/site-packages/sqlalchemy/pool/base.py", line 493, in checkout
    rec = pool._do_get()
  File "/home/airflow/.local/lib/python3.7/site-packages/sqlalchemy/pool/impl.py", line 256, in _do_get
    return self._create_connection()
  File "/home/airflow/.local/lib/python3.7/site-packages/sqlalchemy/pool/base.py", line 273, in _create_connection
    return _ConnectionRecord(self)
  File "/home/airflow/.local/lib/python3.7/site-packages/sqlalchemy/pool/base.py", line 388, in __init__
    self.__connect()
  File "/home/airflow/.local/lib/python3.7/site-packages/sqlalchemy/pool/base.py", line 691, in __connect
    pool.logger.debug("Error on connect(): %s", e)
  File "/home/airflow/.local/lib/python3.7/site-packages/sqlalchemy/util/langhelpers.py", line 72, in __exit__
    with_traceback=exc_tb,
  File "/home/airflow/.local/lib/python3.7/site-packages/sqlalchemy/util/compat.py", line 211, in raise_
    raise exception
  File "/home/airflow/.local/lib/python3.7/site-packages/sqlalchemy/pool/base.py", line 686, in __connect
    self.dbapi_connection = connection = pool._invoke_creator(self)
  File "/home/airflow/.local/lib/python3.7/site-packages/sqlalchemy/engine/create.py", line 574, in connect
    return dialect.connect(*cargs, **cparams)
  File "/home/airflow/.local/lib/python3.7/site-packages/sqlalchemy/engine/default.py", line 598, in connect
    return self.dbapi.connect(*cargs, **cparams)
  File "/home/airflow/.local/lib/python3.7/site-packages/psycopg2/__init__.py", line 122, in connect
    conn = _connect(dsn, connection_factory=connection_factory, **kwasync)
psycopg2.OperationalError: could not translate host name "postgres" to address: Temporary failure in name resolution


The above exception was the direct cause of the following exception:

Traceback (most recent call last):
  File "/home/airflow/.local/lib/python3.7/site-packages/airflow/models/taskinstance.py", line 2611, in schedule_downstream_tasks
    session=session,
  File "/home/airflow/.local/lib/python3.7/site-packages/sqlalchemy/orm/query.py", line 2870, in one
    return self._iter().one()
  File "/home/airflow/.local/lib/python3.7/site-packages/sqlalchemy/orm/query.py", line 2919, in _iter
    execution_options={"_sa_orm_load_options": self.load_options},
  File "/home/airflow/.local/lib/python3.7/site-packages/sqlalchemy/orm/session.py", line 1716, in execute
    conn = self._connection_for_bind(bind)
  File "/home/airflow/.local/lib/python3.7/site-packages/sqlalchemy/orm/session.py", line 1556, in _connection_for_bind
    engine, execution_options
  File "/home/airflow/.local/lib/python3.7/site-packages/sqlalchemy/orm/session.py", line 750, in _connection_for_bind
    conn = bind.connect()
  File "/home/airflow/.local/lib/python3.7/site-packages/sqlalchemy/engine/base.py", line 3320, in connect
    return self._connection_cls(self, close_with_result=close_with_result)
  File "/home/airflow/.local/lib/python3.7/site-packages/sqlalchemy/engine/base.py", line 96, in __init__
    else engine.raw_connection()
  File "/home/airflow/.local/lib/python3.7/site-packages/sqlalchemy/engine/base.py", line 3399, in raw_connection
    return self._wrap_pool_connect(self.pool.connect, _connection)
  File "/home/airflow/.local/lib/python3.7/site-packages/sqlalchemy/engine/base.py", line 3370, in _wrap_pool_connect
    e, dialect, self
  File "/home/airflow/.local/lib/python3.7/site-packages/sqlalchemy/engine/base.py", line 2204, in _handle_dbapi_exception_noconnection
    sqlalchemy_exception, with_traceback=exc_info[2], from_=e
  File "/home/airflow/.local/lib/python3.7/site-packages/sqlalchemy/util/compat.py", line 211, in raise_
    raise exception
  File "/home/airflow/.local/lib/python3.7/site-packages/sqlalchemy/engine/base.py", line 3366, in _wrap_pool_connect
    return fn()
  File "/home/airflow/.local/lib/python3.7/site-packages/sqlalchemy/pool/base.py", line 327, in connect
    return _ConnectionFairy._checkout(self)
  File "/home/airflow/.local/lib/python3.7/site-packages/sqlalchemy/pool/base.py", line 894, in _checkout
    fairy = _ConnectionRecord.checkout(pool)
  File "/home/airflow/.local/lib/python3.7/site-packages/sqlalchemy/pool/base.py", line 493, in checkout
    rec = pool._do_get()
  File "/home/airflow/.local/lib/python3.7/site-packages/sqlalchemy/pool/impl.py", line 256, in _do_get
    return self._create_connection()
  File "/home/airflow/.local/lib/python3.7/site-packages/sqlalchemy/pool/base.py", line 273, in _create_connection
    return _ConnectionRecord(self)
  File "/home/airflow/.local/lib/python3.7/site-packages/sqlalchemy/pool/base.py", line 388, in __init__
    self.__connect()
  File "/home/airflow/.local/lib/python3.7/site-packages/sqlalchemy/pool/base.py", line 691, in __connect
    pool.logger.debug("Error on connect(): %s", e)
  File "/home/airflow/.local/lib/python3.7/site-packages/sqlalchemy/util/langhelpers.py", line 72, in __exit__
    with_traceback=exc_tb,
  File "/home/airflow/.local/lib/python3.7/site-packages/sqlalchemy/util/compat.py", line 211, in raise_
    raise exception
  File "/home/airflow/.local/lib/python3.7/site-packages/sqlalchemy/pool/base.py", line 686, in __connect
    self.dbapi_connection = connection = pool._invoke_creator(self)
  File "/home/airflow/.local/lib/python3.7/site-packages/sqlalchemy/engine/create.py", line 574, in connect
    return dialect.connect(*cargs, **cparams)
  File "/home/airflow/.local/lib/python3.7/site-packages/sqlalchemy/engine/default.py", line 598, in connect
    return self.dbapi.connect(*cargs, **cparams)
  File "/home/airflow/.local/lib/python3.7/site-packages/psycopg2/__init__.py", line 122, in connect
    conn = _connect(dsn, connection_factory=connection_factory, **kwasync)
sqlalchemy.exc.OperationalError: (psycopg2.OperationalError) could not translate host name "postgres" to address: Temporary failure in name resolution

(Background on this error at: https://sqlalche.me/e/14/e3q8)
[2023-06-11T04:45:55.065+0000] {taskinstance.py:1103} INFO - Dependencies all met for dep_context=non-requeueable deps ti=<TaskInstance: first_dag_02.second_task scheduled__2021-08-15T00:00:00+00:00 [queued]>
[2023-06-11T04:45:55.149+0000] {taskinstance.py:1103} INFO - Dependencies all met for dep_context=requeueable deps ti=<TaskInstance: first_dag_02.second_task scheduled__2021-08-15T00:00:00+00:00 [queued]>
[2023-06-11T04:45:55.154+0000] {taskinstance.py:1308} INFO - Starting attempt 1 of 6
[2023-06-11T04:45:55.272+0000] {taskinstance.py:1327} INFO - Executing <Task(BashOperator): second_task> on 2021-08-15 00:00:00+00:00
[2023-06-11T04:45:55.289+0000] {standard_task_runner.py:57} INFO - Started process 337 to run task
[2023-06-11T04:45:55.296+0000] {standard_task_runner.py:84} INFO - Running: ['***', 'tasks', 'run', 'first_dag_02', 'second_task', 'scheduled__2021-08-15T00:00:00+00:00', '--job-id', '94', '--raw', '--subdir', 'DAGS_FOLDER/First_dag.py', '--cfg-path', '/tmp/tmppk1lo6l1']
[2023-06-11T04:45:55.300+0000] {standard_task_runner.py:85} INFO - Job 94: Subtask second_task
[2023-06-11T04:45:55.493+0000] {task_command.py:410} INFO - Running <TaskInstance: first_dag_02.second_task scheduled__2021-08-15T00:00:00+00:00 [running]> on host 4b1b5d40d165
[2023-06-11T04:45:55.992+0000] {taskinstance.py:1547} INFO - Exporting env vars: AIRFLOW_CTX_DAG_OWNER='Raja' AIRFLOW_CTX_DAG_ID='first_dag_02' AIRFLOW_CTX_TASK_ID='second_task' AIRFLOW_CTX_EXECUTION_DATE='2021-08-15T00:00:00+00:00' AIRFLOW_CTX_TRY_NUMBER='1' AIRFLOW_CTX_DAG_RUN_ID='scheduled__2021-08-15T00:00:00+00:00'
[2023-06-11T04:45:55.993+0000] {subprocess.py:63} INFO - Tmp dir root location: 
 /tmp
[2023-06-11T04:45:55.994+0000] {subprocess.py:75} INFO - Running command: ['/bin/bash', '-c', 'echo hey, I am task2 and will be running after task1!']
[2023-06-11T04:45:56.012+0000] {subprocess.py:86} INFO - Output:
[2023-06-11T04:45:56.040+0000] {subprocess.py:93} INFO - hey, I am task2 and will be running after task1!
[2023-06-11T04:45:56.068+0000] {subprocess.py:97} INFO - Command exited with return code 0
[2023-06-11T04:45:56.196+0000] {taskinstance.py:1350} INFO - Marking task as SUCCESS. dag_id=first_dag_02, task_id=second_task, execution_date=20210815T000000, start_date=20230611T044555, end_date=20230611T044556
[2023-06-11T04:45:56.267+0000] {local_task_job_runner.py:225} INFO - Task exited with return code 0
[2023-06-11T04:45:56.350+0000] {taskinstance.py:2651} INFO - 0 downstream tasks scheduled from follow-on schedule check
[2023-06-11T05:16:14.099+0000] {taskinstance.py:1103} INFO - Dependencies all met for dep_context=non-requeueable deps ti=<TaskInstance: first_dag_02.second_task scheduled__2021-08-15T00:00:00+00:00 [queued]>
[2023-06-11T05:16:14.155+0000] {taskinstance.py:1103} INFO - Dependencies all met for dep_context=requeueable deps ti=<TaskInstance: first_dag_02.second_task scheduled__2021-08-15T00:00:00+00:00 [queued]>
[2023-06-11T05:16:14.156+0000] {taskinstance.py:1308} INFO - Starting attempt 1 of 6
[2023-06-11T05:16:14.841+0000] {taskinstance.py:1327} INFO - Executing <Task(BashOperator): second_task> on 2021-08-15 00:00:00+00:00
[2023-06-11T05:16:14.876+0000] {standard_task_runner.py:57} INFO - Started process 354 to run task
[2023-06-11T05:16:14.901+0000] {standard_task_runner.py:84} INFO - Running: ['***', 'tasks', 'run', 'first_dag_02', 'second_task', 'scheduled__2021-08-15T00:00:00+00:00', '--job-id', '86', '--raw', '--subdir', 'DAGS_FOLDER/First_dag.py', '--cfg-path', '/tmp/tmpofr4b4s3']
[2023-06-11T05:16:14.948+0000] {standard_task_runner.py:85} INFO - Job 86: Subtask second_task
[2023-06-11T05:16:16.918+0000] {task_command.py:410} INFO - Running <TaskInstance: first_dag_02.second_task scheduled__2021-08-15T00:00:00+00:00 [running]> on host 69e374580eab
[2023-06-11T05:16:21.164+0000] {taskinstance.py:1547} INFO - Exporting env vars: AIRFLOW_CTX_DAG_OWNER='Raja' AIRFLOW_CTX_DAG_ID='first_dag_02' AIRFLOW_CTX_TASK_ID='second_task' AIRFLOW_CTX_EXECUTION_DATE='2021-08-15T00:00:00+00:00' AIRFLOW_CTX_TRY_NUMBER='1' AIRFLOW_CTX_DAG_RUN_ID='scheduled__2021-08-15T00:00:00+00:00'
[2023-06-11T05:16:21.179+0000] {subprocess.py:63} INFO - Tmp dir root location: 
 /tmp
[2023-06-11T05:16:21.181+0000] {subprocess.py:75} INFO - Running command: ['/bin/bash', '-c', 'echo hey, I am task2 and will be running after task1!']
[2023-06-11T05:16:21.420+0000] {subprocess.py:86} INFO - Output:
[2023-06-11T05:16:21.443+0000] {subprocess.py:93} INFO - hey, I am task2 and will be running after task1!
[2023-06-11T05:16:21.461+0000] {subprocess.py:97} INFO - Command exited with return code 0
[2023-06-11T05:16:21.788+0000] {taskinstance.py:1350} INFO - Marking task as SUCCESS. dag_id=first_dag_02, task_id=second_task, execution_date=20210815T000000, start_date=20230611T051614, end_date=20230611T051621
[2023-06-11T05:16:23.568+0000] {local_task_job_runner.py:225} INFO - Task exited with return code 0
[2023-06-11T05:16:24.115+0000] {taskinstance.py:2651} INFO - 0 downstream tasks scheduled from follow-on schedule check
[2023-06-11T08:18:45.946+0000] {taskinstance.py:1103} INFO - Dependencies all met for dep_context=non-requeueable deps ti=<TaskInstance: first_dag_02.second_task scheduled__2021-08-15T00:00:00+00:00 [queued]>
[2023-06-11T08:18:46.887+0000] {taskinstance.py:1103} INFO - Dependencies all met for dep_context=requeueable deps ti=<TaskInstance: first_dag_02.second_task scheduled__2021-08-15T00:00:00+00:00 [queued]>
[2023-06-11T08:18:46.887+0000] {taskinstance.py:1308} INFO - Starting attempt 1 of 6
[2023-06-11T08:18:48.121+0000] {taskinstance.py:1327} INFO - Executing <Task(BashOperator): second_task> on 2021-08-15 00:00:00+00:00
[2023-06-11T08:18:48.277+0000] {standard_task_runner.py:57} INFO - Started process 481 to run task
[2023-06-11T08:18:48.376+0000] {standard_task_runner.py:84} INFO - Running: ['***', 'tasks', 'run', 'first_dag_02', 'second_task', 'scheduled__2021-08-15T00:00:00+00:00', '--job-id', '163', '--raw', '--subdir', 'DAGS_FOLDER/First_dag.py', '--cfg-path', '/tmp/tmpc3uptnf_']
[2023-06-11T08:18:48.462+0000] {standard_task_runner.py:85} INFO - Job 163: Subtask second_task
[2023-06-11T08:18:49.948+0000] {task_command.py:410} INFO - Running <TaskInstance: first_dag_02.second_task scheduled__2021-08-15T00:00:00+00:00 [running]> on host 492037cdd057
[2023-06-11T08:18:59.388+0000] {taskinstance.py:1547} INFO - Exporting env vars: AIRFLOW_CTX_DAG_OWNER='Raja' AIRFLOW_CTX_DAG_ID='first_dag_02' AIRFLOW_CTX_TASK_ID='second_task' AIRFLOW_CTX_EXECUTION_DATE='2021-08-15T00:00:00+00:00' AIRFLOW_CTX_TRY_NUMBER='1' AIRFLOW_CTX_DAG_RUN_ID='scheduled__2021-08-15T00:00:00+00:00'
[2023-06-11T08:18:59.390+0000] {subprocess.py:63} INFO - Tmp dir root location: 
 /tmp
[2023-06-11T08:18:59.504+0000] {subprocess.py:75} INFO - Running command: ['/bin/bash', '-c', 'echo hey, I am task2 and will be running after task1!']
[2023-06-11T08:19:00.011+0000] {subprocess.py:86} INFO - Output:
[2023-06-11T08:19:00.196+0000] {subprocess.py:93} INFO - hey, I am task2 and will be running after task1!
[2023-06-11T08:19:00.197+0000] {subprocess.py:97} INFO - Command exited with return code 0
[2023-06-11T08:19:01.365+0000] {taskinstance.py:1350} INFO - Marking task as SUCCESS. dag_id=first_dag_02, task_id=second_task, execution_date=20210815T000000, start_date=20230611T081846, end_date=20230611T081901
[2023-06-11T08:19:02.097+0000] {local_task_job_runner.py:225} INFO - Task exited with return code 0
[2023-06-11T08:19:03.818+0000] {taskinstance.py:2651} INFO - 0 downstream tasks scheduled from follow-on schedule check
[2023-06-11T08:48:24.374+0000] {taskinstance.py:1103} INFO - Dependencies all met for dep_context=non-requeueable deps ti=<TaskInstance: first_dag_02.second_task scheduled__2021-08-15T00:00:00+00:00 [queued]>
[2023-06-11T08:48:24.660+0000] {taskinstance.py:1103} INFO - Dependencies all met for dep_context=requeueable deps ti=<TaskInstance: first_dag_02.second_task scheduled__2021-08-15T00:00:00+00:00 [queued]>
[2023-06-11T08:48:24.660+0000] {taskinstance.py:1308} INFO - Starting attempt 1 of 6
[2023-06-11T08:48:24.953+0000] {taskinstance.py:1327} INFO - Executing <Task(BashOperator): second_task> on 2021-08-15 00:00:00+00:00
[2023-06-11T08:48:24.962+0000] {standard_task_runner.py:57} INFO - Started process 430 to run task
[2023-06-11T08:48:24.975+0000] {standard_task_runner.py:84} INFO - Running: ['***', 'tasks', 'run', 'first_dag_02', 'second_task', 'scheduled__2021-08-15T00:00:00+00:00', '--job-id', '126', '--raw', '--subdir', 'DAGS_FOLDER/First_dag.py', '--cfg-path', '/tmp/tmprpzb8z10']
[2023-06-11T08:48:25.017+0000] {standard_task_runner.py:85} INFO - Job 126: Subtask second_task
[2023-06-11T08:48:25.669+0000] {task_command.py:410} INFO - Running <TaskInstance: first_dag_02.second_task scheduled__2021-08-15T00:00:00+00:00 [running]> on host 964e508aad03
[2023-06-11T08:48:26.614+0000] {taskinstance.py:1547} INFO - Exporting env vars: AIRFLOW_CTX_DAG_OWNER='Raja' AIRFLOW_CTX_DAG_ID='first_dag_02' AIRFLOW_CTX_TASK_ID='second_task' AIRFLOW_CTX_EXECUTION_DATE='2021-08-15T00:00:00+00:00' AIRFLOW_CTX_TRY_NUMBER='1' AIRFLOW_CTX_DAG_RUN_ID='scheduled__2021-08-15T00:00:00+00:00'
[2023-06-11T08:48:26.616+0000] {subprocess.py:63} INFO - Tmp dir root location: 
 /tmp
[2023-06-11T08:48:26.618+0000] {subprocess.py:75} INFO - Running command: ['/bin/bash', '-c', 'echo hey, I am task2 and will be running after task1!']
[2023-06-11T08:48:26.651+0000] {subprocess.py:86} INFO - Output:
[2023-06-11T08:48:26.664+0000] {subprocess.py:93} INFO - hey, I am task2 and will be running after task1!
[2023-06-11T08:48:26.665+0000] {subprocess.py:97} INFO - Command exited with return code 0
[2023-06-11T08:48:27.068+0000] {taskinstance.py:1350} INFO - Marking task as SUCCESS. dag_id=first_dag_02, task_id=second_task, execution_date=20210815T000000, start_date=20230611T084824, end_date=20230611T084827
[2023-06-11T08:48:27.607+0000] {local_task_job_runner.py:225} INFO - Task exited with return code 0
[2023-06-11T08:48:28.348+0000] {taskinstance.py:2651} INFO - 0 downstream tasks scheduled from follow-on schedule check
[2023-06-11T10:39:22.131+0000] {taskinstance.py:1103} INFO - Dependencies all met for dep_context=non-requeueable deps ti=<TaskInstance: first_dag_02.second_task scheduled__2021-08-15T00:00:00+00:00 [queued]>
[2023-06-11T10:39:22.757+0000] {taskinstance.py:1103} INFO - Dependencies all met for dep_context=requeueable deps ti=<TaskInstance: first_dag_02.second_task scheduled__2021-08-15T00:00:00+00:00 [queued]>
[2023-06-11T10:39:22.757+0000] {taskinstance.py:1308} INFO - Starting attempt 1 of 6
[2023-06-11T10:39:22.842+0000] {taskinstance.py:1327} INFO - Executing <Task(BashOperator): second_task> on 2021-08-15 00:00:00+00:00
[2023-06-11T10:39:22.874+0000] {standard_task_runner.py:57} INFO - Started process 443 to run task
[2023-06-11T10:39:22.929+0000] {standard_task_runner.py:84} INFO - Running: ['***', 'tasks', 'run', 'first_dag_02', 'second_task', 'scheduled__2021-08-15T00:00:00+00:00', '--job-id', '118', '--raw', '--subdir', 'DAGS_FOLDER/First_dag.py', '--cfg-path', '/tmp/tmp0ydt5jn8']
[2023-06-11T10:39:22.931+0000] {standard_task_runner.py:85} INFO - Job 118: Subtask second_task
[2023-06-11T10:39:25.502+0000] {task_command.py:410} INFO - Running <TaskInstance: first_dag_02.second_task scheduled__2021-08-15T00:00:00+00:00 [running]> on host 7586ce0070ac
[2023-06-11T10:39:29.969+0000] {taskinstance.py:1547} INFO - Exporting env vars: AIRFLOW_CTX_DAG_OWNER='Raja' AIRFLOW_CTX_DAG_ID='first_dag_02' AIRFLOW_CTX_TASK_ID='second_task' AIRFLOW_CTX_EXECUTION_DATE='2021-08-15T00:00:00+00:00' AIRFLOW_CTX_TRY_NUMBER='1' AIRFLOW_CTX_DAG_RUN_ID='scheduled__2021-08-15T00:00:00+00:00'
[2023-06-11T10:39:30.137+0000] {subprocess.py:63} INFO - Tmp dir root location: 
 /tmp
[2023-06-11T10:39:30.154+0000] {subprocess.py:75} INFO - Running command: ['/bin/bash', '-c', 'echo hey, I am task2 and will be running after task1!']
[2023-06-11T10:39:30.864+0000] {subprocess.py:86} INFO - Output:
[2023-06-11T10:39:30.879+0000] {subprocess.py:93} INFO - hey, I am task2 and will be running after task1!
[2023-06-11T10:39:30.880+0000] {subprocess.py:97} INFO - Command exited with return code 0
[2023-06-11T10:39:32.798+0000] {taskinstance.py:1350} INFO - Marking task as SUCCESS. dag_id=first_dag_02, task_id=second_task, execution_date=20210815T000000, start_date=20230611T103922, end_date=20230611T103932
[2023-06-11T10:39:33.377+0000] {local_task_job_runner.py:225} INFO - Task exited with return code 0
[2023-06-11T10:39:33.830+0000] {taskinstance.py:2651} INFO - 0 downstream tasks scheduled from follow-on schedule check
