[2023-06-10T16:38:05.231+0000] {taskinstance.py:1103} INFO - Dependencies all met for dep_context=non-requeueable deps ti=<TaskInstance: dag_pythonoperator.second_task scheduled__2023-06-09T00:00:00+00:00 [queued]>
[2023-06-10T16:38:05.376+0000] {taskinstance.py:1103} INFO - Dependencies all met for dep_context=requeueable deps ti=<TaskInstance: dag_pythonoperator.second_task scheduled__2023-06-09T00:00:00+00:00 [queued]>
[2023-06-10T16:38:05.376+0000] {taskinstance.py:1308} INFO - Starting attempt 2 of 6
[2023-06-10T16:38:05.604+0000] {taskinstance.py:1327} INFO - Executing <Task(PythonOperator): second_task> on 2023-06-09 00:00:00+00:00
[2023-06-10T16:38:05.642+0000] {standard_task_runner.py:57} INFO - Started process 4916 to run task
[2023-06-10T16:38:05.671+0000] {standard_task_runner.py:84} INFO - Running: ['***', 'tasks', 'run', 'dag_pythonoperator', 'second_task', 'scheduled__2023-06-09T00:00:00+00:00', '--job-id', '1500', '--raw', '--subdir', 'DAGS_FOLDER/Pythonoperator_dag.py', '--cfg-path', '/tmp/tmpa_zyypx0']
[2023-06-10T16:38:05.692+0000] {standard_task_runner.py:85} INFO - Job 1500: Subtask second_task
[2023-06-10T16:38:06.815+0000] {task_command.py:410} INFO - Running <TaskInstance: dag_pythonoperator.second_task scheduled__2023-06-09T00:00:00+00:00 [running]> on host e326d5f70fa9
[2023-06-10T16:38:08.519+0000] {taskinstance.py:1547} INFO - Exporting env vars: AIRFLOW_CTX_DAG_OWNER='Raja' AIRFLOW_CTX_DAG_ID='dag_pythonoperator' AIRFLOW_CTX_TASK_ID='second_task' AIRFLOW_CTX_EXECUTION_DATE='2023-06-09T00:00:00+00:00' AIRFLOW_CTX_TRY_NUMBER='2' AIRFLOW_CTX_DAG_RUN_ID='scheduled__2023-06-09T00:00:00+00:00'
[2023-06-10T16:38:08.531+0000] {taskinstance.py:1824} ERROR - Task failed with exception
Traceback (most recent call last):
  File "/home/airflow/.local/lib/python3.7/site-packages/airflow/operators/python.py", line 181, in execute
    return_value = self.execute_callable()
  File "/home/airflow/.local/lib/python3.7/site-packages/airflow/operators/python.py", line 198, in execute_callable
    return self.python_callable(*self.op_args, **self.op_kwargs)
  File "/opt/airflow/dags/Pythonoperator_dag.py", line 16, in retur_values
    first_name=ti.xcom_pull(task_ids=get_name,key='first_name')
  File "/home/airflow/.local/lib/python3.7/site-packages/airflow/utils/session.py", line 76, in wrapper
    return func(*args, session=session, **kwargs)
  File "/home/airflow/.local/lib/python3.7/site-packages/airflow/models/taskinstance.py", line 2441, in xcom_pull
    task_id_whens = {tid: i for i, tid in enumerate(task_ids)}
TypeError: 'function' object is not iterable
[2023-06-10T16:38:08.563+0000] {taskinstance.py:1350} INFO - Marking task as UP_FOR_RETRY. dag_id=dag_pythonoperator, task_id=second_task, execution_date=20230609T000000, start_date=20230610T163805, end_date=20230610T163808
[2023-06-10T16:38:08.634+0000] {standard_task_runner.py:109} ERROR - Failed to execute job 1500 for task second_task ('function' object is not iterable; 4916)
[2023-06-10T16:38:08.711+0000] {local_task_job_runner.py:225} INFO - Task exited with return code 1
[2023-06-10T16:38:09.018+0000] {taskinstance.py:2651} INFO - 0 downstream tasks scheduled from follow-on schedule check
