[2023-06-11T04:45:39.983+0000] {taskinstance.py:1103} INFO - Dependencies all met for dep_context=non-requeueable deps ti=<TaskInstance: dag_pythonoperator.second_task scheduled__2023-06-10T00:00:00+00:00 [queued]>
[2023-06-11T04:45:40.566+0000] {taskinstance.py:1103} INFO - Dependencies all met for dep_context=requeueable deps ti=<TaskInstance: dag_pythonoperator.second_task scheduled__2023-06-10T00:00:00+00:00 [queued]>
[2023-06-11T04:45:40.581+0000] {taskinstance.py:1308} INFO - Starting attempt 1 of 6
[2023-06-11T04:45:41.037+0000] {taskinstance.py:1327} INFO - Executing <Task(PythonOperator): second_task> on 2023-06-10 00:00:00+00:00
[2023-06-11T04:45:41.126+0000] {standard_task_runner.py:57} INFO - Started process 312 to run task
[2023-06-11T04:45:41.143+0000] {standard_task_runner.py:84} INFO - Running: ['***', 'tasks', 'run', 'dag_pythonoperator', 'second_task', 'scheduled__2023-06-10T00:00:00+00:00', '--job-id', '83', '--raw', '--subdir', 'DAGS_FOLDER/python_operator_dag.py', '--cfg-path', '/tmp/tmp5s04zor6']
[2023-06-11T04:45:41.149+0000] {standard_task_runner.py:85} INFO - Job 83: Subtask second_task
[2023-06-11T04:45:42.129+0000] {task_command.py:410} INFO - Running <TaskInstance: dag_pythonoperator.second_task scheduled__2023-06-10T00:00:00+00:00 [running]> on host 4b1b5d40d165
[2023-06-11T04:45:44.726+0000] {taskinstance.py:1547} INFO - Exporting env vars: AIRFLOW_CTX_DAG_OWNER='Raja' AIRFLOW_CTX_DAG_ID='dag_pythonoperator' AIRFLOW_CTX_TASK_ID='second_task' AIRFLOW_CTX_EXECUTION_DATE='2023-06-10T00:00:00+00:00' AIRFLOW_CTX_TRY_NUMBER='1' AIRFLOW_CTX_DAG_RUN_ID='scheduled__2023-06-10T00:00:00+00:00'
[2023-06-11T04:45:44.752+0000] {taskinstance.py:1824} ERROR - Task failed with exception
Traceback (most recent call last):
  File "/home/airflow/.local/lib/python3.7/site-packages/airflow/operators/python.py", line 181, in execute
    return_value = self.execute_callable()
  File "/home/airflow/.local/lib/python3.7/site-packages/airflow/operators/python.py", line 198, in execute_callable
    return self.python_callable(*self.op_args, **self.op_kwargs)
  File "/opt/airflow/dags/python_operator_dag.py", line 16, in retur_values
    first_name=ti.xcom_pull(task_ids=get_name,key='first_name')
  File "/home/airflow/.local/lib/python3.7/site-packages/airflow/utils/session.py", line 76, in wrapper
    return func(*args, session=session, **kwargs)
  File "/home/airflow/.local/lib/python3.7/site-packages/airflow/models/taskinstance.py", line 2441, in xcom_pull
    task_id_whens = {tid: i for i, tid in enumerate(task_ids)}
TypeError: 'function' object is not iterable
[2023-06-11T04:45:44.873+0000] {taskinstance.py:1350} INFO - Marking task as UP_FOR_RETRY. dag_id=dag_pythonoperator, task_id=second_task, execution_date=20230610T000000, start_date=20230611T044539, end_date=20230611T044544
[2023-06-11T04:45:45.223+0000] {standard_task_runner.py:109} ERROR - Failed to execute job 83 for task second_task ('function' object is not iterable; 312)
[2023-06-11T04:45:45.424+0000] {local_task_job_runner.py:225} INFO - Task exited with return code 1
[2023-06-11T04:45:46.206+0000] {taskinstance.py:2651} INFO - 0 downstream tasks scheduled from follow-on schedule check
