[2023-06-12T14:20:18.184+0000] {taskinstance.py:1103} INFO - Dependencies all met for dep_context=non-requeueable deps ti=<TaskInstance: s3_download_dag_07.download_s3_file_task manual__2023-06-12T14:14:46.138537+00:00 [queued]>
[2023-06-12T14:20:18.254+0000] {taskinstance.py:1103} INFO - Dependencies all met for dep_context=requeueable deps ti=<TaskInstance: s3_download_dag_07.download_s3_file_task manual__2023-06-12T14:14:46.138537+00:00 [queued]>
[2023-06-12T14:20:18.255+0000] {taskinstance.py:1308} INFO - Starting attempt 2 of 2
[2023-06-12T14:20:18.315+0000] {taskinstance.py:1327} INFO - Executing <Task(PythonOperator): download_s3_file_task> on 2023-06-12 14:14:46.138537+00:00
[2023-06-12T14:20:18.323+0000] {standard_task_runner.py:57} INFO - Started process 172 to run task
[2023-06-12T14:20:18.333+0000] {standard_task_runner.py:84} INFO - Running: ['***', 'tasks', 'run', 's3_download_dag_07', 'download_s3_file_task', 'manual__2023-06-12T14:14:46.138537+00:00', '--job-id', '343', '--raw', '--subdir', 'DAGS_FOLDER/download_s3_dag.py', '--cfg-path', '/tmp/tmpfmas8q9t']
[2023-06-12T14:20:18.334+0000] {standard_task_runner.py:85} INFO - Job 343: Subtask download_s3_file_task
[2023-06-12T14:20:18.496+0000] {task_command.py:410} INFO - Running <TaskInstance: s3_download_dag_07.download_s3_file_task manual__2023-06-12T14:14:46.138537+00:00 [running]> on host 03cd9a7904e9
[2023-06-12T14:20:18.882+0000] {taskinstance.py:1547} INFO - Exporting env vars: AIRFLOW_CTX_DAG_OWNER='Raja' AIRFLOW_CTX_DAG_ID='s3_download_dag_07' AIRFLOW_CTX_TASK_ID='download_s3_file_task' AIRFLOW_CTX_EXECUTION_DATE='2023-06-12T14:14:46.138537+00:00' AIRFLOW_CTX_TRY_NUMBER='2' AIRFLOW_CTX_DAG_RUN_ID='manual__2023-06-12T14:14:46.138537+00:00'
[2023-06-12T14:20:18.891+0000] {s3.py:971} INFO - This function shadows the 'download_file' method of S3 API, but it is not the same. If you want to use the original method from S3 API, please call 'S3Hook.get_conn().download_file()'
[2023-06-12T14:20:18.891+0000] {s3.py:976} INFO - Downloading source S3 file from Bucket main.txt with path s3firstexample
[2023-06-12T14:20:18.918+0000] {base.py:73} INFO - Using connection ID 'S3_conn' for task execution.
[2023-06-12T14:20:18.919+0000] {connection_wrapper.py:337} INFO - AWS Connection (conn_id='S3_conn', conn_type='aws') credentials retrieved from login and password.
[2023-06-12T14:20:31.257+0000] {taskinstance.py:1824} ERROR - Task failed with exception
Traceback (most recent call last):
  File "/home/airflow/.local/lib/python3.7/site-packages/airflow/operators/python.py", line 181, in execute
    return_value = self.execute_callable()
  File "/home/airflow/.local/lib/python3.7/site-packages/airflow/operators/python.py", line 198, in execute_callable
    return self.python_callable(*self.op_args, **self.op_kwargs)
  File "/opt/airflow/dags/download_s3_dag.py", line 22, in download_s3_file
    s3_hook.download_file(bucket_name, key, local_filepath)
  File "/home/airflow/.local/lib/python3.7/site-packages/airflow/providers/amazon/aws/hooks/s3.py", line 111, in wrapper
    return func(*bound_args.args, **bound_args.kwargs)
  File "/home/airflow/.local/lib/python3.7/site-packages/airflow/providers/amazon/aws/hooks/s3.py", line 82, in wrapper
    return func(*bound_args.args, **bound_args.kwargs)
  File "/home/airflow/.local/lib/python3.7/site-packages/airflow/providers/amazon/aws/hooks/s3.py", line 986, in download_file
    raise e
  File "/home/airflow/.local/lib/python3.7/site-packages/airflow/providers/amazon/aws/hooks/s3.py", line 979, in download_file
    s3_obj = self.get_key(key, bucket_name)
  File "/home/airflow/.local/lib/python3.7/site-packages/airflow/providers/amazon/aws/hooks/s3.py", line 111, in wrapper
    return func(*bound_args.args, **bound_args.kwargs)
  File "/home/airflow/.local/lib/python3.7/site-packages/airflow/providers/amazon/aws/hooks/s3.py", line 82, in wrapper
    return func(*bound_args.args, **bound_args.kwargs)
  File "/home/airflow/.local/lib/python3.7/site-packages/airflow/providers/amazon/aws/hooks/s3.py", line 542, in get_key
    obj.load()
  File "/home/airflow/.local/lib/python3.7/site-packages/boto3/resources/factory.py", line 564, in do_action
    response = action(self, *args, **kwargs)
  File "/home/airflow/.local/lib/python3.7/site-packages/boto3/resources/action.py", line 88, in __call__
    response = getattr(parent.meta.client, operation_name)(*args, **params)
  File "/home/airflow/.local/lib/python3.7/site-packages/botocore/client.py", line 530, in _api_call
    return self._make_api_call(operation_name, kwargs)
  File "/home/airflow/.local/lib/python3.7/site-packages/botocore/client.py", line 960, in _make_api_call
    raise error_class(parsed_response, operation_name)
botocore.exceptions.ClientError: An error occurred (404) when calling the HeadObject operation: Not Found
[2023-06-12T14:20:31.295+0000] {taskinstance.py:1350} INFO - Marking task as FAILED. dag_id=s3_download_dag_07, task_id=download_s3_file_task, execution_date=20230612T141446, start_date=20230612T142018, end_date=20230612T142031
[2023-06-12T14:20:31.338+0000] {standard_task_runner.py:109} ERROR - Failed to execute job 343 for task download_s3_file_task (An error occurred (404) when calling the HeadObject operation: Not Found; 172)
[2023-06-12T14:20:31.414+0000] {local_task_job_runner.py:225} INFO - Task exited with return code 1
[2023-06-12T14:20:31.509+0000] {taskinstance.py:2651} INFO - 0 downstream tasks scheduled from follow-on schedule check
