[2023-06-10T17:29:27.586+0000] {taskinstance.py:1103} INFO - Dependencies all met for dep_context=non-requeueable deps ti=<TaskInstance: first_dag_02.thrid_task scheduled__2021-08-18T00:00:00+00:00 [queued]>
[2023-06-10T17:29:31.669+0000] {taskinstance.py:1103} INFO - Dependencies all met for dep_context=requeueable deps ti=<TaskInstance: first_dag_02.thrid_task scheduled__2021-08-18T00:00:00+00:00 [queued]>
[2023-06-10T17:29:31.671+0000] {taskinstance.py:1308} INFO - Starting attempt 1 of 6
[2023-06-10T17:29:33.013+0000] {taskinstance.py:1327} INFO - Executing <Task(BashOperator): thrid_task> on 2021-08-18 00:00:00+00:00
[2023-06-10T17:29:33.248+0000] {standard_task_runner.py:84} INFO - Running: ['***', 'tasks', 'run', 'first_dag_02', 'thrid_task', 'scheduled__2021-08-18T00:00:00+00:00', '--job-id', '1857', '--raw', '--subdir', 'DAGS_FOLDER/First_dag.py', '--cfg-path', '/tmp/tmpvk4zyscn']
[2023-06-10T17:29:33.252+0000] {standard_task_runner.py:85} INFO - Job 1857: Subtask thrid_task
[2023-06-10T17:29:33.327+0000] {standard_task_runner.py:57} INFO - Started process 1072 to run task
[2023-06-10T17:29:42.171+0000] {task_command.py:410} INFO - Running <TaskInstance: first_dag_02.thrid_task scheduled__2021-08-18T00:00:00+00:00 [running]> on host e326d5f70fa9
[2023-06-10T17:30:14.660+0000] {taskinstance.py:1824} ERROR - Task failed with exception
Traceback (most recent call last):
  File "/home/airflow/.local/lib/python3.7/site-packages/sqlalchemy/engine/base.py", line 3366, in _wrap_pool_connect
    return fn()
  File "/home/airflow/.local/lib/python3.7/site-packages/sqlalchemy/pool/base.py", line 327, in connect
    return _ConnectionFairy._checkout(self)
  File "/home/airflow/.local/lib/python3.7/site-packages/sqlalchemy/pool/base.py", line 894, in _checkout
    fairy = _ConnectionRecord.checkout(pool)
  File "/home/airflow/.local/lib/python3.7/site-packages/sqlalchemy/pool/base.py", line 493, in checkout
    rec = pool._do_get()
  File "/home/airflow/.local/lib/python3.7/site-packages/sqlalchemy/pool/impl.py", line 256, in _do_get
    return self._create_connection()
  File "/home/airflow/.local/lib/python3.7/site-packages/sqlalchemy/pool/base.py", line 273, in _create_connection
    return _ConnectionRecord(self)
  File "/home/airflow/.local/lib/python3.7/site-packages/sqlalchemy/pool/base.py", line 388, in __init__
    self.__connect()
  File "/home/airflow/.local/lib/python3.7/site-packages/sqlalchemy/pool/base.py", line 691, in __connect
    pool.logger.debug("Error on connect(): %s", e)
  File "/home/airflow/.local/lib/python3.7/site-packages/sqlalchemy/util/langhelpers.py", line 72, in __exit__
    with_traceback=exc_tb,
  File "/home/airflow/.local/lib/python3.7/site-packages/sqlalchemy/util/compat.py", line 211, in raise_
    raise exception
  File "/home/airflow/.local/lib/python3.7/site-packages/sqlalchemy/pool/base.py", line 686, in __connect
    self.dbapi_connection = connection = pool._invoke_creator(self)
  File "/home/airflow/.local/lib/python3.7/site-packages/sqlalchemy/engine/create.py", line 574, in connect
    return dialect.connect(*cargs, **cparams)
  File "/home/airflow/.local/lib/python3.7/site-packages/sqlalchemy/engine/default.py", line 598, in connect
    return self.dbapi.connect(*cargs, **cparams)
  File "/home/airflow/.local/lib/python3.7/site-packages/psycopg2/__init__.py", line 122, in connect
    conn = _connect(dsn, connection_factory=connection_factory, **kwasync)
psycopg2.OperationalError: could not translate host name "postgres" to address: Temporary failure in name resolution


The above exception was the direct cause of the following exception:

Traceback (most recent call last):
  File "/home/airflow/.local/lib/python3.7/site-packages/airflow/models/taskinstance.py", line 1407, in _run_raw_task
    self._execute_task_with_callbacks(context, test_mode)
  File "/home/airflow/.local/lib/python3.7/site-packages/airflow/models/taskinstance.py", line 1535, in _execute_task_with_callbacks
    RenderedTaskInstanceFields.delete_old_records(self.task_id, self.dag_id)
  File "/home/airflow/.local/lib/python3.7/site-packages/airflow/utils/session.py", line 76, in wrapper
    return func(*args, session=session, **kwargs)
  File "/home/airflow/.local/lib/python3.7/site-packages/airflow/models/renderedtifields.py", line 223, in delete_old_records
    session=session,
  File "/home/airflow/.local/lib/python3.7/site-packages/airflow/utils/retries.py", line 78, in wrapped_function
    for attempt in run_with_db_retries(max_retries=retries, logger=logger, **retry_kwargs):
  File "/home/airflow/.local/lib/python3.7/site-packages/tenacity/__init__.py", line 347, in __iter__
    do = self.iter(retry_state=retry_state)
  File "/home/airflow/.local/lib/python3.7/site-packages/tenacity/__init__.py", line 325, in iter
    raise retry_exc.reraise()
  File "/home/airflow/.local/lib/python3.7/site-packages/tenacity/__init__.py", line 158, in reraise
    raise self.last_attempt.result()
  File "/usr/local/lib/python3.7/concurrent/futures/_base.py", line 428, in result
    return self.__get_result()
  File "/usr/local/lib/python3.7/concurrent/futures/_base.py", line 384, in __get_result
    raise self._exception
  File "/home/airflow/.local/lib/python3.7/site-packages/airflow/utils/retries.py", line 87, in wrapped_function
    return func(*args, **kwargs)
  File "/home/airflow/.local/lib/python3.7/site-packages/airflow/models/renderedtifields.py", line 245, in _do_delete_old_records
    ).delete(synchronize_session=False)
  File "/home/airflow/.local/lib/python3.7/site-packages/sqlalchemy/orm/query.py", line 3225, in delete
    execution_options={"synchronize_session": synchronize_session},
  File "/home/airflow/.local/lib/python3.7/site-packages/sqlalchemy/orm/session.py", line 1716, in execute
    conn = self._connection_for_bind(bind)
  File "/home/airflow/.local/lib/python3.7/site-packages/sqlalchemy/orm/session.py", line 1556, in _connection_for_bind
    engine, execution_options
  File "/home/airflow/.local/lib/python3.7/site-packages/sqlalchemy/orm/session.py", line 750, in _connection_for_bind
    conn = bind.connect()
  File "/home/airflow/.local/lib/python3.7/site-packages/sqlalchemy/engine/base.py", line 3320, in connect
    return self._connection_cls(self, close_with_result=close_with_result)
  File "/home/airflow/.local/lib/python3.7/site-packages/sqlalchemy/engine/base.py", line 96, in __init__
    else engine.raw_connection()
  File "/home/airflow/.local/lib/python3.7/site-packages/sqlalchemy/engine/base.py", line 3399, in raw_connection
    return self._wrap_pool_connect(self.pool.connect, _connection)
  File "/home/airflow/.local/lib/python3.7/site-packages/sqlalchemy/engine/base.py", line 3370, in _wrap_pool_connect
    e, dialect, self
  File "/home/airflow/.local/lib/python3.7/site-packages/sqlalchemy/engine/base.py", line 2204, in _handle_dbapi_exception_noconnection
    sqlalchemy_exception, with_traceback=exc_info[2], from_=e
  File "/home/airflow/.local/lib/python3.7/site-packages/sqlalchemy/util/compat.py", line 211, in raise_
    raise exception
  File "/home/airflow/.local/lib/python3.7/site-packages/sqlalchemy/engine/base.py", line 3366, in _wrap_pool_connect
    return fn()
  File "/home/airflow/.local/lib/python3.7/site-packages/sqlalchemy/pool/base.py", line 327, in connect
    return _ConnectionFairy._checkout(self)
  File "/home/airflow/.local/lib/python3.7/site-packages/sqlalchemy/pool/base.py", line 894, in _checkout
    fairy = _ConnectionRecord.checkout(pool)
  File "/home/airflow/.local/lib/python3.7/site-packages/sqlalchemy/pool/base.py", line 493, in checkout
    rec = pool._do_get()
  File "/home/airflow/.local/lib/python3.7/site-packages/sqlalchemy/pool/impl.py", line 256, in _do_get
    return self._create_connection()
  File "/home/airflow/.local/lib/python3.7/site-packages/sqlalchemy/pool/base.py", line 273, in _create_connection
    return _ConnectionRecord(self)
  File "/home/airflow/.local/lib/python3.7/site-packages/sqlalchemy/pool/base.py", line 388, in __init__
    self.__connect()
  File "/home/airflow/.local/lib/python3.7/site-packages/sqlalchemy/pool/base.py", line 691, in __connect
    pool.logger.debug("Error on connect(): %s", e)
  File "/home/airflow/.local/lib/python3.7/site-packages/sqlalchemy/util/langhelpers.py", line 72, in __exit__
    with_traceback=exc_tb,
  File "/home/airflow/.local/lib/python3.7/site-packages/sqlalchemy/util/compat.py", line 211, in raise_
    raise exception
  File "/home/airflow/.local/lib/python3.7/site-packages/sqlalchemy/pool/base.py", line 686, in __connect
    self.dbapi_connection = connection = pool._invoke_creator(self)
  File "/home/airflow/.local/lib/python3.7/site-packages/sqlalchemy/engine/create.py", line 574, in connect
    return dialect.connect(*cargs, **cparams)
  File "/home/airflow/.local/lib/python3.7/site-packages/sqlalchemy/engine/default.py", line 598, in connect
    return self.dbapi.connect(*cargs, **cparams)
  File "/home/airflow/.local/lib/python3.7/site-packages/psycopg2/__init__.py", line 122, in connect
    conn = _connect(dsn, connection_factory=connection_factory, **kwasync)
sqlalchemy.exc.OperationalError: (psycopg2.OperationalError) could not translate host name "postgres" to address: Temporary failure in name resolution

(Background on this error at: https://sqlalche.me/e/14/e3q8)
[2023-06-10T17:30:15.189+0000] {standard_task_runner.py:109} ERROR - Failed to execute job 1857 for task thrid_task ((psycopg2.OperationalError) could not translate host name "postgres" to address: Temporary failure in name resolution

(Background on this error at: https://sqlalche.me/e/14/e3q8); 1072)
[2023-06-10T17:30:15.265+0000] {local_task_job_runner.py:225} INFO - Task exited with return code 1
[2023-06-10T17:30:15.287+0000] {taskinstance.py:2660} INFO - Skipping mini scheduling run due to exception: None
Traceback (most recent call last):
  File "/home/airflow/.local/lib/python3.7/site-packages/sqlalchemy/engine/base.py", line 3366, in _wrap_pool_connect
    return fn()
  File "/home/airflow/.local/lib/python3.7/site-packages/sqlalchemy/pool/base.py", line 327, in connect
    return _ConnectionFairy._checkout(self)
  File "/home/airflow/.local/lib/python3.7/site-packages/sqlalchemy/pool/base.py", line 894, in _checkout
    fairy = _ConnectionRecord.checkout(pool)
  File "/home/airflow/.local/lib/python3.7/site-packages/sqlalchemy/pool/base.py", line 493, in checkout
    rec = pool._do_get()
  File "/home/airflow/.local/lib/python3.7/site-packages/sqlalchemy/pool/impl.py", line 256, in _do_get
    return self._create_connection()
  File "/home/airflow/.local/lib/python3.7/site-packages/sqlalchemy/pool/base.py", line 273, in _create_connection
    return _ConnectionRecord(self)
  File "/home/airflow/.local/lib/python3.7/site-packages/sqlalchemy/pool/base.py", line 388, in __init__
    self.__connect()
  File "/home/airflow/.local/lib/python3.7/site-packages/sqlalchemy/pool/base.py", line 691, in __connect
    pool.logger.debug("Error on connect(): %s", e)
  File "/home/airflow/.local/lib/python3.7/site-packages/sqlalchemy/util/langhelpers.py", line 72, in __exit__
    with_traceback=exc_tb,
  File "/home/airflow/.local/lib/python3.7/site-packages/sqlalchemy/util/compat.py", line 211, in raise_
    raise exception
  File "/home/airflow/.local/lib/python3.7/site-packages/sqlalchemy/pool/base.py", line 686, in __connect
    self.dbapi_connection = connection = pool._invoke_creator(self)
  File "/home/airflow/.local/lib/python3.7/site-packages/sqlalchemy/engine/create.py", line 574, in connect
    return dialect.connect(*cargs, **cparams)
  File "/home/airflow/.local/lib/python3.7/site-packages/sqlalchemy/engine/default.py", line 598, in connect
    return self.dbapi.connect(*cargs, **cparams)
  File "/home/airflow/.local/lib/python3.7/site-packages/psycopg2/__init__.py", line 122, in connect
    conn = _connect(dsn, connection_factory=connection_factory, **kwasync)
psycopg2.OperationalError: could not translate host name "postgres" to address: Temporary failure in name resolution


The above exception was the direct cause of the following exception:

Traceback (most recent call last):
  File "/home/airflow/.local/lib/python3.7/site-packages/airflow/models/taskinstance.py", line 2611, in schedule_downstream_tasks
    session=session,
  File "/home/airflow/.local/lib/python3.7/site-packages/sqlalchemy/orm/query.py", line 2870, in one
    return self._iter().one()
  File "/home/airflow/.local/lib/python3.7/site-packages/sqlalchemy/orm/query.py", line 2919, in _iter
    execution_options={"_sa_orm_load_options": self.load_options},
  File "/home/airflow/.local/lib/python3.7/site-packages/sqlalchemy/orm/session.py", line 1716, in execute
    conn = self._connection_for_bind(bind)
  File "/home/airflow/.local/lib/python3.7/site-packages/sqlalchemy/orm/session.py", line 1556, in _connection_for_bind
    engine, execution_options
  File "/home/airflow/.local/lib/python3.7/site-packages/sqlalchemy/orm/session.py", line 750, in _connection_for_bind
    conn = bind.connect()
  File "/home/airflow/.local/lib/python3.7/site-packages/sqlalchemy/engine/base.py", line 3320, in connect
    return self._connection_cls(self, close_with_result=close_with_result)
  File "/home/airflow/.local/lib/python3.7/site-packages/sqlalchemy/engine/base.py", line 96, in __init__
    else engine.raw_connection()
  File "/home/airflow/.local/lib/python3.7/site-packages/sqlalchemy/engine/base.py", line 3399, in raw_connection
    return self._wrap_pool_connect(self.pool.connect, _connection)
  File "/home/airflow/.local/lib/python3.7/site-packages/sqlalchemy/engine/base.py", line 3370, in _wrap_pool_connect
    e, dialect, self
  File "/home/airflow/.local/lib/python3.7/site-packages/sqlalchemy/engine/base.py", line 2204, in _handle_dbapi_exception_noconnection
    sqlalchemy_exception, with_traceback=exc_info[2], from_=e
  File "/home/airflow/.local/lib/python3.7/site-packages/sqlalchemy/util/compat.py", line 211, in raise_
    raise exception
  File "/home/airflow/.local/lib/python3.7/site-packages/sqlalchemy/engine/base.py", line 3366, in _wrap_pool_connect
    return fn()
  File "/home/airflow/.local/lib/python3.7/site-packages/sqlalchemy/pool/base.py", line 327, in connect
    return _ConnectionFairy._checkout(self)
  File "/home/airflow/.local/lib/python3.7/site-packages/sqlalchemy/pool/base.py", line 894, in _checkout
    fairy = _ConnectionRecord.checkout(pool)
  File "/home/airflow/.local/lib/python3.7/site-packages/sqlalchemy/pool/base.py", line 493, in checkout
    rec = pool._do_get()
  File "/home/airflow/.local/lib/python3.7/site-packages/sqlalchemy/pool/impl.py", line 256, in _do_get
    return self._create_connection()
  File "/home/airflow/.local/lib/python3.7/site-packages/sqlalchemy/pool/base.py", line 273, in _create_connection
    return _ConnectionRecord(self)
  File "/home/airflow/.local/lib/python3.7/site-packages/sqlalchemy/pool/base.py", line 388, in __init__
    self.__connect()
  File "/home/airflow/.local/lib/python3.7/site-packages/sqlalchemy/pool/base.py", line 691, in __connect
    pool.logger.debug("Error on connect(): %s", e)
  File "/home/airflow/.local/lib/python3.7/site-packages/sqlalchemy/util/langhelpers.py", line 72, in __exit__
    with_traceback=exc_tb,
  File "/home/airflow/.local/lib/python3.7/site-packages/sqlalchemy/util/compat.py", line 211, in raise_
    raise exception
  File "/home/airflow/.local/lib/python3.7/site-packages/sqlalchemy/pool/base.py", line 686, in __connect
    self.dbapi_connection = connection = pool._invoke_creator(self)
  File "/home/airflow/.local/lib/python3.7/site-packages/sqlalchemy/engine/create.py", line 574, in connect
    return dialect.connect(*cargs, **cparams)
  File "/home/airflow/.local/lib/python3.7/site-packages/sqlalchemy/engine/default.py", line 598, in connect
    return self.dbapi.connect(*cargs, **cparams)
  File "/home/airflow/.local/lib/python3.7/site-packages/psycopg2/__init__.py", line 122, in connect
    conn = _connect(dsn, connection_factory=connection_factory, **kwasync)
sqlalchemy.exc.OperationalError: (psycopg2.OperationalError) could not translate host name "postgres" to address: Temporary failure in name resolution

(Background on this error at: https://sqlalche.me/e/14/e3q8)
[2023-06-11T04:46:10.694+0000] {taskinstance.py:1103} INFO - Dependencies all met for dep_context=non-requeueable deps ti=<TaskInstance: first_dag_02.thrid_task scheduled__2021-08-18T00:00:00+00:00 [queued]>
[2023-06-11T04:46:10.792+0000] {taskinstance.py:1103} INFO - Dependencies all met for dep_context=requeueable deps ti=<TaskInstance: first_dag_02.thrid_task scheduled__2021-08-18T00:00:00+00:00 [queued]>
[2023-06-11T04:46:10.793+0000] {taskinstance.py:1308} INFO - Starting attempt 1 of 6
[2023-06-11T04:46:10.976+0000] {taskinstance.py:1327} INFO - Executing <Task(BashOperator): thrid_task> on 2021-08-18 00:00:00+00:00
[2023-06-11T04:46:10.996+0000] {standard_task_runner.py:57} INFO - Started process 372 to run task
[2023-06-11T04:46:11.029+0000] {standard_task_runner.py:84} INFO - Running: ['***', 'tasks', 'run', 'first_dag_02', 'thrid_task', 'scheduled__2021-08-18T00:00:00+00:00', '--job-id', '106', '--raw', '--subdir', 'DAGS_FOLDER/First_dag.py', '--cfg-path', '/tmp/tmptbf2ww9g']
[2023-06-11T04:46:11.031+0000] {standard_task_runner.py:85} INFO - Job 106: Subtask thrid_task
[2023-06-11T04:46:11.514+0000] {task_command.py:410} INFO - Running <TaskInstance: first_dag_02.thrid_task scheduled__2021-08-18T00:00:00+00:00 [running]> on host 4b1b5d40d165
[2023-06-11T04:46:12.111+0000] {taskinstance.py:1547} INFO - Exporting env vars: AIRFLOW_CTX_DAG_OWNER='Raja' AIRFLOW_CTX_DAG_ID='first_dag_02' AIRFLOW_CTX_TASK_ID='thrid_task' AIRFLOW_CTX_EXECUTION_DATE='2021-08-18T00:00:00+00:00' AIRFLOW_CTX_TRY_NUMBER='1' AIRFLOW_CTX_DAG_RUN_ID='scheduled__2021-08-18T00:00:00+00:00'
[2023-06-11T04:46:12.115+0000] {subprocess.py:63} INFO - Tmp dir root location: 
 /tmp
[2023-06-11T04:46:12.117+0000] {subprocess.py:75} INFO - Running command: ['/bin/bash', '-c', 'echo hey, I am task3 and will be running after task1 at the same time as task2!']
[2023-06-11T04:46:12.140+0000] {subprocess.py:86} INFO - Output:
[2023-06-11T04:46:12.148+0000] {subprocess.py:93} INFO - hey, I am task3 and will be running after task1 at the same time as task2!
[2023-06-11T04:46:12.151+0000] {subprocess.py:97} INFO - Command exited with return code 0
[2023-06-11T04:46:12.313+0000] {taskinstance.py:1350} INFO - Marking task as SUCCESS. dag_id=first_dag_02, task_id=thrid_task, execution_date=20210818T000000, start_date=20230611T044610, end_date=20230611T044612
[2023-06-11T04:46:12.406+0000] {local_task_job_runner.py:225} INFO - Task exited with return code 0
[2023-06-11T04:46:12.471+0000] {taskinstance.py:2651} INFO - 0 downstream tasks scheduled from follow-on schedule check
[2023-06-11T05:16:23.696+0000] {taskinstance.py:1103} INFO - Dependencies all met for dep_context=non-requeueable deps ti=<TaskInstance: first_dag_02.thrid_task scheduled__2021-08-18T00:00:00+00:00 [queued]>
[2023-06-11T05:16:24.088+0000] {taskinstance.py:1103} INFO - Dependencies all met for dep_context=requeueable deps ti=<TaskInstance: first_dag_02.thrid_task scheduled__2021-08-18T00:00:00+00:00 [queued]>
[2023-06-11T05:16:24.089+0000] {taskinstance.py:1308} INFO - Starting attempt 1 of 6
[2023-06-11T05:16:24.482+0000] {taskinstance.py:1327} INFO - Executing <Task(BashOperator): thrid_task> on 2021-08-18 00:00:00+00:00
[2023-06-11T05:16:24.651+0000] {standard_task_runner.py:84} INFO - Running: ['***', 'tasks', 'run', 'first_dag_02', 'thrid_task', 'scheduled__2021-08-18T00:00:00+00:00', '--job-id', '91', '--raw', '--subdir', 'DAGS_FOLDER/First_dag.py', '--cfg-path', '/tmp/tmp2zhlkf1_']
[2023-06-11T05:16:24.666+0000] {standard_task_runner.py:85} INFO - Job 91: Subtask thrid_task
[2023-06-11T05:16:24.557+0000] {standard_task_runner.py:57} INFO - Started process 366 to run task
[2023-06-11T05:16:25.074+0000] {task_command.py:410} INFO - Running <TaskInstance: first_dag_02.thrid_task scheduled__2021-08-18T00:00:00+00:00 [running]> on host 69e374580eab
[2023-06-11T05:16:26.929+0000] {taskinstance.py:1547} INFO - Exporting env vars: AIRFLOW_CTX_DAG_OWNER='Raja' AIRFLOW_CTX_DAG_ID='first_dag_02' AIRFLOW_CTX_TASK_ID='thrid_task' AIRFLOW_CTX_EXECUTION_DATE='2021-08-18T00:00:00+00:00' AIRFLOW_CTX_TRY_NUMBER='1' AIRFLOW_CTX_DAG_RUN_ID='scheduled__2021-08-18T00:00:00+00:00'
[2023-06-11T05:16:26.944+0000] {subprocess.py:63} INFO - Tmp dir root location: 
 /tmp
[2023-06-11T05:16:26.945+0000] {subprocess.py:75} INFO - Running command: ['/bin/bash', '-c', 'echo hey, I am task3 and will be running after task1 at the same time as task2!']
[2023-06-11T05:16:27.349+0000] {subprocess.py:86} INFO - Output:
[2023-06-11T05:16:27.369+0000] {subprocess.py:93} INFO - hey, I am task3 and will be running after task1 at the same time as task2!
[2023-06-11T05:16:27.398+0000] {subprocess.py:97} INFO - Command exited with return code 0
[2023-06-11T05:16:28.099+0000] {taskinstance.py:1350} INFO - Marking task as SUCCESS. dag_id=first_dag_02, task_id=thrid_task, execution_date=20210818T000000, start_date=20230611T051623, end_date=20230611T051628
[2023-06-11T05:16:28.572+0000] {local_task_job_runner.py:225} INFO - Task exited with return code 0
[2023-06-11T05:16:29.040+0000] {taskinstance.py:2651} INFO - 0 downstream tasks scheduled from follow-on schedule check
[2023-06-11T08:19:17.505+0000] {taskinstance.py:1103} INFO - Dependencies all met for dep_context=non-requeueable deps ti=<TaskInstance: first_dag_02.thrid_task scheduled__2021-08-18T00:00:00+00:00 [queued]>
[2023-06-11T08:19:18.374+0000] {taskinstance.py:1103} INFO - Dependencies all met for dep_context=requeueable deps ti=<TaskInstance: first_dag_02.thrid_task scheduled__2021-08-18T00:00:00+00:00 [queued]>
[2023-06-11T08:19:18.388+0000] {taskinstance.py:1308} INFO - Starting attempt 1 of 6
[2023-06-11T08:19:19.668+0000] {taskinstance.py:1327} INFO - Executing <Task(BashOperator): thrid_task> on 2021-08-18 00:00:00+00:00
[2023-06-11T08:19:19.912+0000] {standard_task_runner.py:57} INFO - Started process 523 to run task
[2023-06-11T08:19:20.072+0000] {standard_task_runner.py:84} INFO - Running: ['***', 'tasks', 'run', 'first_dag_02', 'thrid_task', 'scheduled__2021-08-18T00:00:00+00:00', '--job-id', '173', '--raw', '--subdir', 'DAGS_FOLDER/First_dag.py', '--cfg-path', '/tmp/tmp412k9vkv']
[2023-06-11T08:19:20.073+0000] {standard_task_runner.py:85} INFO - Job 173: Subtask thrid_task
[2023-06-11T08:19:21.214+0000] {task_command.py:410} INFO - Running <TaskInstance: first_dag_02.thrid_task scheduled__2021-08-18T00:00:00+00:00 [running]> on host 492037cdd057
[2023-06-11T08:19:29.066+0000] {taskinstance.py:1547} INFO - Exporting env vars: AIRFLOW_CTX_DAG_OWNER='Raja' AIRFLOW_CTX_DAG_ID='first_dag_02' AIRFLOW_CTX_TASK_ID='thrid_task' AIRFLOW_CTX_EXECUTION_DATE='2021-08-18T00:00:00+00:00' AIRFLOW_CTX_TRY_NUMBER='1' AIRFLOW_CTX_DAG_RUN_ID='scheduled__2021-08-18T00:00:00+00:00'
[2023-06-11T08:19:29.185+0000] {subprocess.py:63} INFO - Tmp dir root location: 
 /tmp
[2023-06-11T08:19:29.190+0000] {subprocess.py:75} INFO - Running command: ['/bin/bash', '-c', 'echo hey, I am task3 and will be running after task1 at the same time as task2!']
[2023-06-11T08:19:29.412+0000] {subprocess.py:86} INFO - Output:
[2023-06-11T08:19:29.697+0000] {subprocess.py:93} INFO - hey, I am task3 and will be running after task1 at the same time as task2!
[2023-06-11T08:19:29.719+0000] {subprocess.py:97} INFO - Command exited with return code 0
[2023-06-11T08:19:31.228+0000] {taskinstance.py:1350} INFO - Marking task as SUCCESS. dag_id=first_dag_02, task_id=thrid_task, execution_date=20210818T000000, start_date=20230611T081917, end_date=20230611T081931
[2023-06-11T08:19:32.623+0000] {local_task_job_runner.py:225} INFO - Task exited with return code 0
[2023-06-11T08:19:33.423+0000] {taskinstance.py:2651} INFO - 0 downstream tasks scheduled from follow-on schedule check
[2023-06-11T08:48:27.159+0000] {taskinstance.py:1103} INFO - Dependencies all met for dep_context=non-requeueable deps ti=<TaskInstance: first_dag_02.thrid_task scheduled__2021-08-18T00:00:00+00:00 [queued]>
[2023-06-11T08:48:27.394+0000] {taskinstance.py:1103} INFO - Dependencies all met for dep_context=requeueable deps ti=<TaskInstance: first_dag_02.thrid_task scheduled__2021-08-18T00:00:00+00:00 [queued]>
[2023-06-11T08:48:27.395+0000] {taskinstance.py:1308} INFO - Starting attempt 1 of 6
[2023-06-11T08:48:28.151+0000] {taskinstance.py:1327} INFO - Executing <Task(BashOperator): thrid_task> on 2021-08-18 00:00:00+00:00
[2023-06-11T08:48:28.221+0000] {standard_task_runner.py:57} INFO - Started process 440 to run task
[2023-06-11T08:48:28.251+0000] {standard_task_runner.py:84} INFO - Running: ['***', 'tasks', 'run', 'first_dag_02', 'thrid_task', 'scheduled__2021-08-18T00:00:00+00:00', '--job-id', '132', '--raw', '--subdir', 'DAGS_FOLDER/First_dag.py', '--cfg-path', '/tmp/tmpjwoe6_fb']
[2023-06-11T08:48:28.251+0000] {standard_task_runner.py:85} INFO - Job 132: Subtask thrid_task
[2023-06-11T08:48:28.978+0000] {task_command.py:410} INFO - Running <TaskInstance: first_dag_02.thrid_task scheduled__2021-08-18T00:00:00+00:00 [running]> on host 964e508aad03
[2023-06-11T08:48:31.403+0000] {taskinstance.py:1547} INFO - Exporting env vars: AIRFLOW_CTX_DAG_OWNER='Raja' AIRFLOW_CTX_DAG_ID='first_dag_02' AIRFLOW_CTX_TASK_ID='thrid_task' AIRFLOW_CTX_EXECUTION_DATE='2021-08-18T00:00:00+00:00' AIRFLOW_CTX_TRY_NUMBER='1' AIRFLOW_CTX_DAG_RUN_ID='scheduled__2021-08-18T00:00:00+00:00'
[2023-06-11T08:48:31.421+0000] {subprocess.py:63} INFO - Tmp dir root location: 
 /tmp
[2023-06-11T08:48:31.422+0000] {subprocess.py:75} INFO - Running command: ['/bin/bash', '-c', 'echo hey, I am task3 and will be running after task1 at the same time as task2!']
[2023-06-11T08:48:31.554+0000] {subprocess.py:86} INFO - Output:
[2023-06-11T08:48:31.575+0000] {subprocess.py:93} INFO - hey, I am task3 and will be running after task1 at the same time as task2!
[2023-06-11T08:48:31.575+0000] {subprocess.py:97} INFO - Command exited with return code 0
[2023-06-11T08:48:31.965+0000] {taskinstance.py:1350} INFO - Marking task as SUCCESS. dag_id=first_dag_02, task_id=thrid_task, execution_date=20210818T000000, start_date=20230611T084827, end_date=20230611T084831
[2023-06-11T08:48:32.194+0000] {local_task_job_runner.py:225} INFO - Task exited with return code 0
[2023-06-11T08:48:32.516+0000] {taskinstance.py:2651} INFO - 0 downstream tasks scheduled from follow-on schedule check
[2023-06-11T10:40:10.390+0000] {taskinstance.py:1103} INFO - Dependencies all met for dep_context=non-requeueable deps ti=<TaskInstance: first_dag_02.thrid_task scheduled__2021-08-18T00:00:00+00:00 [queued]>
[2023-06-11T10:40:10.765+0000] {taskinstance.py:1103} INFO - Dependencies all met for dep_context=requeueable deps ti=<TaskInstance: first_dag_02.thrid_task scheduled__2021-08-18T00:00:00+00:00 [queued]>
[2023-06-11T10:40:10.766+0000] {taskinstance.py:1308} INFO - Starting attempt 1 of 6
[2023-06-11T10:40:12.374+0000] {taskinstance.py:1327} INFO - Executing <Task(BashOperator): thrid_task> on 2021-08-18 00:00:00+00:00
[2023-06-11T10:40:12.590+0000] {standard_task_runner.py:57} INFO - Started process 522 to run task
[2023-06-11T10:40:12.784+0000] {standard_task_runner.py:84} INFO - Running: ['***', 'tasks', 'run', 'first_dag_02', 'thrid_task', 'scheduled__2021-08-18T00:00:00+00:00', '--job-id', '144', '--raw', '--subdir', 'DAGS_FOLDER/First_dag.py', '--cfg-path', '/tmp/tmp3q8cc8b5']
[2023-06-11T10:40:12.785+0000] {standard_task_runner.py:85} INFO - Job 144: Subtask thrid_task
[2023-06-11T10:40:13.769+0000] {task_command.py:410} INFO - Running <TaskInstance: first_dag_02.thrid_task scheduled__2021-08-18T00:00:00+00:00 [running]> on host 7586ce0070ac
[2023-06-11T10:40:17.192+0000] {taskinstance.py:1547} INFO - Exporting env vars: AIRFLOW_CTX_DAG_OWNER='Raja' AIRFLOW_CTX_DAG_ID='first_dag_02' AIRFLOW_CTX_TASK_ID='thrid_task' AIRFLOW_CTX_EXECUTION_DATE='2021-08-18T00:00:00+00:00' AIRFLOW_CTX_TRY_NUMBER='1' AIRFLOW_CTX_DAG_RUN_ID='scheduled__2021-08-18T00:00:00+00:00'
[2023-06-11T10:40:17.200+0000] {subprocess.py:63} INFO - Tmp dir root location: 
 /tmp
[2023-06-11T10:40:17.202+0000] {subprocess.py:75} INFO - Running command: ['/bin/bash', '-c', 'echo hey, I am task3 and will be running after task1 at the same time as task2!']
[2023-06-11T10:40:17.422+0000] {subprocess.py:86} INFO - Output:
[2023-06-11T10:40:17.427+0000] {subprocess.py:93} INFO - hey, I am task3 and will be running after task1 at the same time as task2!
[2023-06-11T10:40:17.429+0000] {subprocess.py:97} INFO - Command exited with return code 0
[2023-06-11T10:40:17.943+0000] {taskinstance.py:1350} INFO - Marking task as SUCCESS. dag_id=first_dag_02, task_id=thrid_task, execution_date=20210818T000000, start_date=20230611T104010, end_date=20230611T104017
[2023-06-11T10:40:18.399+0000] {local_task_job_runner.py:225} INFO - Task exited with return code 0
[2023-06-11T10:40:18.719+0000] {taskinstance.py:2651} INFO - 0 downstream tasks scheduled from follow-on schedule check
