[2023-06-11T09:45:09.302+0000] {taskinstance.py:1103} INFO - Dependencies all met for dep_context=non-requeueable deps ti=<TaskInstance: dag_cron_expression_03.task1 scheduled__2022-01-19T03:00:00+00:00 [queued]>
[2023-06-11T09:45:09.370+0000] {taskinstance.py:1103} INFO - Dependencies all met for dep_context=requeueable deps ti=<TaskInstance: dag_cron_expression_03.task1 scheduled__2022-01-19T03:00:00+00:00 [queued]>
[2023-06-11T09:45:09.375+0000] {taskinstance.py:1308} INFO - Starting attempt 1 of 6
[2023-06-11T09:45:09.962+0000] {taskinstance.py:1327} INFO - Executing <Task(BashOperator): task1> on 2022-01-19 03:00:00+00:00
[2023-06-11T09:45:09.980+0000] {standard_task_runner.py:57} INFO - Started process 4630 to run task
[2023-06-11T09:45:09.991+0000] {standard_task_runner.py:84} INFO - Running: ['***', 'tasks', 'run', 'dag_cron_expression_03', 'task1', 'scheduled__2022-01-19T03:00:00+00:00', '--job-id', '1420', '--raw', '--subdir', 'DAGS_FOLDER/dag_corn.py', '--cfg-path', '/tmp/tmpf7kmzuh_']
[2023-06-11T09:45:09.992+0000] {standard_task_runner.py:85} INFO - Job 1420: Subtask task1
[2023-06-11T09:45:10.503+0000] {task_command.py:410} INFO - Running <TaskInstance: dag_cron_expression_03.task1 scheduled__2022-01-19T03:00:00+00:00 [running]> on host 964e508aad03
[2023-06-11T09:45:13.782+0000] {taskinstance.py:1547} INFO - Exporting env vars: AIRFLOW_CTX_DAG_OWNER='Raja' AIRFLOW_CTX_DAG_ID='dag_cron_expression_03' AIRFLOW_CTX_TASK_ID='task1' AIRFLOW_CTX_EXECUTION_DATE='2022-01-19T03:00:00+00:00' AIRFLOW_CTX_TRY_NUMBER='1' AIRFLOW_CTX_DAG_RUN_ID='scheduled__2022-01-19T03:00:00+00:00'
[2023-06-11T09:45:13.815+0000] {subprocess.py:63} INFO - Tmp dir root location: 
 /tmp
[2023-06-11T09:45:13.834+0000] {subprocess.py:75} INFO - Running command: ['/bin/bash', '-c', 'echo dag with cron expression!']
[2023-06-11T09:45:14.014+0000] {subprocess.py:86} INFO - Output:
[2023-06-11T09:45:14.031+0000] {subprocess.py:93} INFO - dag with cron expression!
[2023-06-11T09:45:14.037+0000] {subprocess.py:97} INFO - Command exited with return code 0
[2023-06-11T09:45:14.626+0000] {taskinstance.py:1350} INFO - Marking task as SUCCESS. dag_id=dag_cron_expression_03, task_id=task1, execution_date=20220119T030000, start_date=20230611T094509, end_date=20230611T094514
[2023-06-11T09:45:15.404+0000] {local_task_job_runner.py:225} INFO - Task exited with return code 0
[2023-06-11T09:45:16.037+0000] {taskinstance.py:2651} INFO - 0 downstream tasks scheduled from follow-on schedule check
[2023-06-11T10:44:59.238+0000] {taskinstance.py:1103} INFO - Dependencies all met for dep_context=non-requeueable deps ti=<TaskInstance: dag_cron_expression_03.task1 scheduled__2022-01-19T03:00:00+00:00 [queued]>
[2023-06-11T10:44:59.328+0000] {taskinstance.py:1103} INFO - Dependencies all met for dep_context=requeueable deps ti=<TaskInstance: dag_cron_expression_03.task1 scheduled__2022-01-19T03:00:00+00:00 [queued]>
[2023-06-11T10:44:59.329+0000] {taskinstance.py:1308} INFO - Starting attempt 1 of 6
[2023-06-11T10:45:00.948+0000] {taskinstance.py:1327} INFO - Executing <Task(BashOperator): task1> on 2022-01-19 03:00:00+00:00
[2023-06-11T10:45:01.057+0000] {standard_task_runner.py:57} INFO - Started process 879 to run task
[2023-06-11T10:45:01.805+0000] {standard_task_runner.py:84} INFO - Running: ['***', 'tasks', 'run', 'dag_cron_expression_03', 'task1', 'scheduled__2022-01-19T03:00:00+00:00', '--job-id', '245', '--raw', '--subdir', 'DAGS_FOLDER/dag_cron.py', '--cfg-path', '/tmp/tmpyvaj1_b0']
[2023-06-11T10:45:02.062+0000] {standard_task_runner.py:85} INFO - Job 245: Subtask task1
[2023-06-11T10:45:04.042+0000] {task_command.py:410} INFO - Running <TaskInstance: dag_cron_expression_03.task1 scheduled__2022-01-19T03:00:00+00:00 [running]> on host 7586ce0070ac
[2023-06-11T10:45:14.433+0000] {taskinstance.py:1547} INFO - Exporting env vars: AIRFLOW_CTX_DAG_OWNER='Raja' AIRFLOW_CTX_DAG_ID='dag_cron_expression_03' AIRFLOW_CTX_TASK_ID='task1' AIRFLOW_CTX_EXECUTION_DATE='2022-01-19T03:00:00+00:00' AIRFLOW_CTX_TRY_NUMBER='1' AIRFLOW_CTX_DAG_RUN_ID='scheduled__2022-01-19T03:00:00+00:00'
[2023-06-11T10:45:14.915+0000] {subprocess.py:63} INFO - Tmp dir root location: 
 /tmp
[2023-06-11T10:45:14.924+0000] {subprocess.py:75} INFO - Running command: ['/bin/bash', '-c', 'echo dag with cron expression!']
[2023-06-11T10:45:15.512+0000] {subprocess.py:86} INFO - Output:
[2023-06-11T10:45:16.303+0000] {subprocess.py:93} INFO - dag with cron expression!
[2023-06-11T10:45:16.391+0000] {subprocess.py:97} INFO - Command exited with return code 0
[2023-06-11T10:45:23.733+0000] {taskinstance.py:1350} INFO - Marking task as SUCCESS. dag_id=dag_cron_expression_03, task_id=task1, execution_date=20220119T030000, start_date=20230611T104459, end_date=20230611T104523
[2023-06-11T10:45:58.003+0000] {job.py:216} ERROR - Job heartbeat got an exception
Traceback (most recent call last):
  File "/home/airflow/.local/lib/python3.7/site-packages/sqlalchemy/engine/base.py", line 3366, in _wrap_pool_connect
    return fn()
  File "/home/airflow/.local/lib/python3.7/site-packages/sqlalchemy/pool/base.py", line 327, in connect
    return _ConnectionFairy._checkout(self)
  File "/home/airflow/.local/lib/python3.7/site-packages/sqlalchemy/pool/base.py", line 894, in _checkout
    fairy = _ConnectionRecord.checkout(pool)
  File "/home/airflow/.local/lib/python3.7/site-packages/sqlalchemy/pool/base.py", line 493, in checkout
    rec = pool._do_get()
  File "/home/airflow/.local/lib/python3.7/site-packages/sqlalchemy/pool/impl.py", line 256, in _do_get
    return self._create_connection()
  File "/home/airflow/.local/lib/python3.7/site-packages/sqlalchemy/pool/base.py", line 273, in _create_connection
    return _ConnectionRecord(self)
  File "/home/airflow/.local/lib/python3.7/site-packages/sqlalchemy/pool/base.py", line 388, in __init__
    self.__connect()
  File "/home/airflow/.local/lib/python3.7/site-packages/sqlalchemy/pool/base.py", line 691, in __connect
    pool.logger.debug("Error on connect(): %s", e)
  File "/home/airflow/.local/lib/python3.7/site-packages/sqlalchemy/util/langhelpers.py", line 72, in __exit__
    with_traceback=exc_tb,
  File "/home/airflow/.local/lib/python3.7/site-packages/sqlalchemy/util/compat.py", line 211, in raise_
    raise exception
  File "/home/airflow/.local/lib/python3.7/site-packages/sqlalchemy/pool/base.py", line 686, in __connect
    self.dbapi_connection = connection = pool._invoke_creator(self)
  File "/home/airflow/.local/lib/python3.7/site-packages/sqlalchemy/engine/create.py", line 574, in connect
    return dialect.connect(*cargs, **cparams)
  File "/home/airflow/.local/lib/python3.7/site-packages/sqlalchemy/engine/default.py", line 598, in connect
    return self.dbapi.connect(*cargs, **cparams)
  File "/home/airflow/.local/lib/python3.7/site-packages/psycopg2/__init__.py", line 122, in connect
    conn = _connect(dsn, connection_factory=connection_factory, **kwasync)
psycopg2.OperationalError: could not translate host name "postgres" to address: Temporary failure in name resolution


The above exception was the direct cause of the following exception:

Traceback (most recent call last):
  File "/home/airflow/.local/lib/python3.7/site-packages/airflow/jobs/job.py", line 187, in heartbeat
    session.merge(self)
  File "/home/airflow/.local/lib/python3.7/site-packages/sqlalchemy/orm/session.py", line 3062, in merge
    _resolve_conflict_map=_resolve_conflict_map,
  File "/home/airflow/.local/lib/python3.7/site-packages/sqlalchemy/orm/session.py", line 3140, in _merge
    options=options,
  File "/home/airflow/.local/lib/python3.7/site-packages/sqlalchemy/orm/session.py", line 2861, in get
    execution_options=execution_options,
  File "/home/airflow/.local/lib/python3.7/site-packages/sqlalchemy/orm/session.py", line 2979, in _get_impl
    load_options=load_options,
  File "/home/airflow/.local/lib/python3.7/site-packages/sqlalchemy/orm/loading.py", line 534, in load_on_pk_identity
    bind_arguments=bind_arguments,
  File "/home/airflow/.local/lib/python3.7/site-packages/sqlalchemy/orm/session.py", line 1716, in execute
    conn = self._connection_for_bind(bind)
  File "/home/airflow/.local/lib/python3.7/site-packages/sqlalchemy/orm/session.py", line 1556, in _connection_for_bind
    engine, execution_options
  File "/home/airflow/.local/lib/python3.7/site-packages/sqlalchemy/orm/session.py", line 750, in _connection_for_bind
    conn = bind.connect()
  File "/home/airflow/.local/lib/python3.7/site-packages/sqlalchemy/engine/base.py", line 3320, in connect
    return self._connection_cls(self, close_with_result=close_with_result)
  File "/home/airflow/.local/lib/python3.7/site-packages/sqlalchemy/engine/base.py", line 96, in __init__
    else engine.raw_connection()
  File "/home/airflow/.local/lib/python3.7/site-packages/sqlalchemy/engine/base.py", line 3399, in raw_connection
    return self._wrap_pool_connect(self.pool.connect, _connection)
  File "/home/airflow/.local/lib/python3.7/site-packages/sqlalchemy/engine/base.py", line 3370, in _wrap_pool_connect
    e, dialect, self
  File "/home/airflow/.local/lib/python3.7/site-packages/sqlalchemy/engine/base.py", line 2204, in _handle_dbapi_exception_noconnection
    sqlalchemy_exception, with_traceback=exc_info[2], from_=e
  File "/home/airflow/.local/lib/python3.7/site-packages/sqlalchemy/util/compat.py", line 211, in raise_
    raise exception
  File "/home/airflow/.local/lib/python3.7/site-packages/sqlalchemy/engine/base.py", line 3366, in _wrap_pool_connect
    return fn()
  File "/home/airflow/.local/lib/python3.7/site-packages/sqlalchemy/pool/base.py", line 327, in connect
    return _ConnectionFairy._checkout(self)
  File "/home/airflow/.local/lib/python3.7/site-packages/sqlalchemy/pool/base.py", line 894, in _checkout
    fairy = _ConnectionRecord.checkout(pool)
  File "/home/airflow/.local/lib/python3.7/site-packages/sqlalchemy/pool/base.py", line 493, in checkout
    rec = pool._do_get()
  File "/home/airflow/.local/lib/python3.7/site-packages/sqlalchemy/pool/impl.py", line 256, in _do_get
    return self._create_connection()
  File "/home/airflow/.local/lib/python3.7/site-packages/sqlalchemy/pool/base.py", line 273, in _create_connection
    return _ConnectionRecord(self)
  File "/home/airflow/.local/lib/python3.7/site-packages/sqlalchemy/pool/base.py", line 388, in __init__
    self.__connect()
  File "/home/airflow/.local/lib/python3.7/site-packages/sqlalchemy/pool/base.py", line 691, in __connect
    pool.logger.debug("Error on connect(): %s", e)
  File "/home/airflow/.local/lib/python3.7/site-packages/sqlalchemy/util/langhelpers.py", line 72, in __exit__
    with_traceback=exc_tb,
  File "/home/airflow/.local/lib/python3.7/site-packages/sqlalchemy/util/compat.py", line 211, in raise_
    raise exception
  File "/home/airflow/.local/lib/python3.7/site-packages/sqlalchemy/pool/base.py", line 686, in __connect
    self.dbapi_connection = connection = pool._invoke_creator(self)
  File "/home/airflow/.local/lib/python3.7/site-packages/sqlalchemy/engine/create.py", line 574, in connect
    return dialect.connect(*cargs, **cparams)
  File "/home/airflow/.local/lib/python3.7/site-packages/sqlalchemy/engine/default.py", line 598, in connect
    return self.dbapi.connect(*cargs, **cparams)
  File "/home/airflow/.local/lib/python3.7/site-packages/psycopg2/__init__.py", line 122, in connect
    conn = _connect(dsn, connection_factory=connection_factory, **kwasync)
sqlalchemy.exc.OperationalError: (psycopg2.OperationalError) could not translate host name "postgres" to address: Temporary failure in name resolution

(Background on this error at: https://sqlalche.me/e/14/e3q8)
[2023-06-11T10:47:49.190+0000] {local_task_job_runner.py:225} INFO - Task exited with return code 0
[2023-06-11T10:47:53.825+0000] {taskinstance.py:2651} INFO - 0 downstream tasks scheduled from follow-on schedule check
