[2023-06-12T07:16:34.429+0000] {taskinstance.py:1103} INFO - Dependencies all met for dep_context=non-requeueable deps ti=<TaskInstance: s3_upload_dag_19.upload_to_s3 manual__2023-06-12T07:16:30.651673+00:00 [queued]>
[2023-06-12T07:16:34.507+0000] {taskinstance.py:1103} INFO - Dependencies all met for dep_context=requeueable deps ti=<TaskInstance: s3_upload_dag_19.upload_to_s3 manual__2023-06-12T07:16:30.651673+00:00 [queued]>
[2023-06-12T07:16:34.508+0000] {taskinstance.py:1308} INFO - Starting attempt 1 of 2
[2023-06-12T07:16:34.599+0000] {taskinstance.py:1327} INFO - Executing <Task(PythonOperator): upload_to_s3> on 2023-06-12 07:16:30.651673+00:00
[2023-06-12T07:16:34.614+0000] {standard_task_runner.py:57} INFO - Started process 767 to run task
[2023-06-12T07:16:34.631+0000] {standard_task_runner.py:84} INFO - Running: ['***', 'tasks', 'run', 's3_upload_dag_19', 'upload_to_s3', 'manual__2023-06-12T07:16:30.651673+00:00', '--job-id', '287', '--raw', '--subdir', 'DAGS_FOLDER/s3_dag.py', '--cfg-path', '/tmp/tmpag0o9psv']
[2023-06-12T07:16:34.632+0000] {standard_task_runner.py:85} INFO - Job 287: Subtask upload_to_s3
[2023-06-12T07:16:34.952+0000] {task_command.py:410} INFO - Running <TaskInstance: s3_upload_dag_19.upload_to_s3 manual__2023-06-12T07:16:30.651673+00:00 [running]> on host 03cd9a7904e9
[2023-06-12T07:16:35.778+0000] {taskinstance.py:1547} INFO - Exporting env vars: AIRFLOW_CTX_DAG_OWNER='Raja' AIRFLOW_CTX_DAG_ID='s3_upload_dag_19' AIRFLOW_CTX_TASK_ID='upload_to_s3' AIRFLOW_CTX_EXECUTION_DATE='2023-06-12T07:16:30.651673+00:00' AIRFLOW_CTX_TRY_NUMBER='1' AIRFLOW_CTX_DAG_RUN_ID='manual__2023-06-12T07:16:30.651673+00:00'
[2023-06-12T07:16:35.840+0000] {base.py:73} INFO - Using connection ID 'S3_config' for task execution.
[2023-06-12T07:16:35.842+0000] {connection_wrapper.py:337} INFO - AWS Connection (conn_id='S3_config', conn_type='aws') credentials retrieved from login and password.
[2023-06-12T07:16:44.519+0000] {taskinstance.py:1824} ERROR - Task failed with exception
Traceback (most recent call last):
  File "/home/airflow/.local/lib/python3.7/site-packages/airflow/operators/python.py", line 181, in execute
    return_value = self.execute_callable()
  File "/home/airflow/.local/lib/python3.7/site-packages/airflow/operators/python.py", line 198, in execute_callable
    return self.python_callable(*self.op_args, **self.op_kwargs)
  File "/opt/airflow/dags/s3_dag.py", line 20, in upload_to_s3
    hook.load_file(filename=filename, key=key, bucket_name=bucket_name)
  File "/home/airflow/.local/lib/python3.7/site-packages/airflow/providers/amazon/aws/hooks/s3.py", line 111, in wrapper
    return func(*bound_args.args, **bound_args.kwargs)
  File "/home/airflow/.local/lib/python3.7/site-packages/airflow/providers/amazon/aws/hooks/s3.py", line 82, in wrapper
    return func(*bound_args.args, **bound_args.kwargs)
  File "/home/airflow/.local/lib/python3.7/site-packages/airflow/providers/amazon/aws/hooks/s3.py", line 677, in load_file
    raise ValueError(f"The key {key} already exists.")
ValueError: The key test.txt already exists.
[2023-06-12T07:16:44.561+0000] {taskinstance.py:1350} INFO - Marking task as UP_FOR_RETRY. dag_id=s3_upload_dag_19, task_id=upload_to_s3, execution_date=20230612T071630, start_date=20230612T071634, end_date=20230612T071644
[2023-06-12T07:16:44.656+0000] {standard_task_runner.py:109} ERROR - Failed to execute job 287 for task upload_to_s3 (The key test.txt already exists.; 767)
[2023-06-12T07:16:44.712+0000] {local_task_job_runner.py:225} INFO - Task exited with return code 1
[2023-06-12T07:16:44.768+0000] {taskinstance.py:2651} INFO - 0 downstream tasks scheduled from follow-on schedule check
