[2023-06-11T04:51:38.008+0000] {taskinstance.py:1103} INFO - Dependencies all met for dep_context=non-requeueable deps ti=<TaskInstance: dag_pythonoperator_00.second_task scheduled__2023-06-05T00:00:00+00:00 [queued]>
[2023-06-11T04:51:39.295+0000] {taskinstance.py:1103} INFO - Dependencies all met for dep_context=requeueable deps ti=<TaskInstance: dag_pythonoperator_00.second_task scheduled__2023-06-05T00:00:00+00:00 [queued]>
[2023-06-11T04:51:39.301+0000] {taskinstance.py:1308} INFO - Starting attempt 1 of 6
[2023-06-11T04:51:40.143+0000] {taskinstance.py:1327} INFO - Executing <Task(PythonOperator): second_task> on 2023-06-05 00:00:00+00:00
[2023-06-11T04:51:40.427+0000] {standard_task_runner.py:84} INFO - Running: ['***', 'tasks', 'run', 'dag_pythonoperator_00', 'second_task', 'scheduled__2023-06-05T00:00:00+00:00', '--job-id', '261', '--raw', '--subdir', 'DAGS_FOLDER/python_operator_dag.py', '--cfg-path', '/tmp/tmpb8xng2t4']
[2023-06-11T04:51:40.436+0000] {standard_task_runner.py:85} INFO - Job 261: Subtask second_task
[2023-06-11T04:51:40.401+0000] {standard_task_runner.py:57} INFO - Started process 885 to run task
[2023-06-11T04:51:40.972+0000] {task_command.py:410} INFO - Running <TaskInstance: dag_pythonoperator_00.second_task scheduled__2023-06-05T00:00:00+00:00 [running]> on host 4b1b5d40d165
[2023-06-11T04:51:46.550+0000] {taskinstance.py:1547} INFO - Exporting env vars: AIRFLOW_CTX_DAG_OWNER='Raja' AIRFLOW_CTX_DAG_ID='dag_pythonoperator_00' AIRFLOW_CTX_TASK_ID='second_task' AIRFLOW_CTX_EXECUTION_DATE='2023-06-05T00:00:00+00:00' AIRFLOW_CTX_TRY_NUMBER='1' AIRFLOW_CTX_DAG_RUN_ID='scheduled__2023-06-05T00:00:00+00:00'
[2023-06-11T04:51:47.116+0000] {taskinstance.py:1824} ERROR - Task failed with exception
Traceback (most recent call last):
  File "/home/airflow/.local/lib/python3.7/site-packages/airflow/operators/python.py", line 181, in execute
    return_value = self.execute_callable()
  File "/home/airflow/.local/lib/python3.7/site-packages/airflow/operators/python.py", line 198, in execute_callable
    return self.python_callable(*self.op_args, **self.op_kwargs)
  File "/opt/airflow/dags/python_operator_dag.py", line 16, in retur_values
    first_name=ti.xcom_pull(task_ids=get_name,key='first_name')
  File "/home/airflow/.local/lib/python3.7/site-packages/airflow/utils/session.py", line 76, in wrapper
    return func(*args, session=session, **kwargs)
  File "/home/airflow/.local/lib/python3.7/site-packages/airflow/models/taskinstance.py", line 2441, in xcom_pull
    task_id_whens = {tid: i for i, tid in enumerate(task_ids)}
TypeError: 'function' object is not iterable
[2023-06-11T04:51:48.204+0000] {taskinstance.py:1350} INFO - Marking task as UP_FOR_RETRY. dag_id=dag_pythonoperator_00, task_id=second_task, execution_date=20230605T000000, start_date=20230611T045138, end_date=20230611T045148
[2023-06-11T04:51:51.714+0000] {standard_task_runner.py:109} ERROR - Failed to execute job 261 for task second_task ('function' object is not iterable; 885)
[2023-06-11T04:51:52.170+0000] {local_task_job_runner.py:225} INFO - Task exited with return code 1
[2023-06-11T04:51:54.895+0000] {taskinstance.py:2651} INFO - 0 downstream tasks scheduled from follow-on schedule check
[2023-06-11T05:22:09.809+0000] {taskinstance.py:1103} INFO - Dependencies all met for dep_context=non-requeueable deps ti=<TaskInstance: dag_pythonoperator_00.second_task scheduled__2023-06-05T00:00:00+00:00 [queued]>
[2023-06-11T05:22:10.185+0000] {taskinstance.py:1103} INFO - Dependencies all met for dep_context=requeueable deps ti=<TaskInstance: dag_pythonoperator_00.second_task scheduled__2023-06-05T00:00:00+00:00 [queued]>
[2023-06-11T05:22:10.199+0000] {taskinstance.py:1308} INFO - Starting attempt 1 of 6
[2023-06-11T05:22:10.697+0000] {taskinstance.py:1327} INFO - Executing <Task(PythonOperator): second_task> on 2023-06-05 00:00:00+00:00
[2023-06-11T05:22:10.771+0000] {standard_task_runner.py:57} INFO - Started process 909 to run task
[2023-06-11T05:22:10.791+0000] {standard_task_runner.py:84} INFO - Running: ['***', 'tasks', 'run', 'dag_pythonoperator_00', 'second_task', 'scheduled__2023-06-05T00:00:00+00:00', '--job-id', '261', '--raw', '--subdir', 'DAGS_FOLDER/python_operator_dag.py', '--cfg-path', '/tmp/tmp7xok4ay0']
[2023-06-11T05:22:10.794+0000] {standard_task_runner.py:85} INFO - Job 261: Subtask second_task
[2023-06-11T05:22:12.316+0000] {task_command.py:410} INFO - Running <TaskInstance: dag_pythonoperator_00.second_task scheduled__2023-06-05T00:00:00+00:00 [running]> on host 69e374580eab
[2023-06-11T05:22:14.332+0000] {taskinstance.py:1547} INFO - Exporting env vars: AIRFLOW_CTX_DAG_OWNER='Raja' AIRFLOW_CTX_DAG_ID='dag_pythonoperator_00' AIRFLOW_CTX_TASK_ID='second_task' AIRFLOW_CTX_EXECUTION_DATE='2023-06-05T00:00:00+00:00' AIRFLOW_CTX_TRY_NUMBER='1' AIRFLOW_CTX_DAG_RUN_ID='scheduled__2023-06-05T00:00:00+00:00'
[2023-06-11T05:22:14.361+0000] {taskinstance.py:1824} ERROR - Task failed with exception
Traceback (most recent call last):
  File "/home/airflow/.local/lib/python3.7/site-packages/airflow/operators/python.py", line 181, in execute
    return_value = self.execute_callable()
  File "/home/airflow/.local/lib/python3.7/site-packages/airflow/operators/python.py", line 198, in execute_callable
    return self.python_callable(*self.op_args, **self.op_kwargs)
  File "/opt/airflow/dags/python_operator_dag.py", line 16, in retur_values
    first_name=ti.xcom_pull(task_ids=get_name,key='first_name')
  File "/home/airflow/.local/lib/python3.7/site-packages/airflow/utils/session.py", line 76, in wrapper
    return func(*args, session=session, **kwargs)
  File "/home/airflow/.local/lib/python3.7/site-packages/airflow/models/taskinstance.py", line 2441, in xcom_pull
    task_id_whens = {tid: i for i, tid in enumerate(task_ids)}
TypeError: 'function' object is not iterable
[2023-06-11T05:22:14.466+0000] {taskinstance.py:1350} INFO - Marking task as UP_FOR_RETRY. dag_id=dag_pythonoperator_00, task_id=second_task, execution_date=20230605T000000, start_date=20230611T052209, end_date=20230611T052214
[2023-06-11T05:22:14.733+0000] {standard_task_runner.py:109} ERROR - Failed to execute job 261 for task second_task ('function' object is not iterable; 909)
[2023-06-11T05:22:14.898+0000] {local_task_job_runner.py:225} INFO - Task exited with return code 1
[2023-06-11T05:22:15.731+0000] {taskinstance.py:2651} INFO - 0 downstream tasks scheduled from follow-on schedule check
