[2023-06-11T04:57:43.723+0000] {taskinstance.py:1103} INFO - Dependencies all met for dep_context=non-requeueable deps ti=<TaskInstance: first_dag_02.second_task scheduled__2021-11-03T00:00:00+00:00 [queued]>
[2023-06-11T04:57:44.773+0000] {taskinstance.py:1103} INFO - Dependencies all met for dep_context=requeueable deps ti=<TaskInstance: first_dag_02.second_task scheduled__2021-11-03T00:00:00+00:00 [queued]>
[2023-06-11T04:57:44.775+0000] {taskinstance.py:1308} INFO - Starting attempt 1 of 6
[2023-06-11T04:57:46.712+0000] {taskinstance.py:1327} INFO - Executing <Task(BashOperator): second_task> on 2021-11-03 00:00:00+00:00
[2023-06-11T04:57:46.748+0000] {standard_task_runner.py:57} INFO - Started process 1240 to run task
[2023-06-11T04:57:47.180+0000] {standard_task_runner.py:84} INFO - Running: ['***', 'tasks', 'run', 'first_dag_02', 'second_task', 'scheduled__2021-11-03T00:00:00+00:00', '--job-id', '368', '--raw', '--subdir', 'DAGS_FOLDER/First_dag.py', '--cfg-path', '/tmp/tmpr5xc0v0p']
[2023-06-11T04:57:47.290+0000] {standard_task_runner.py:85} INFO - Job 368: Subtask second_task
[2023-06-11T04:57:47.344+0000] {cli_action_loggers.py:135} WARNING - Failed to log action (psycopg2.OperationalError) could not translate host name "postgres" to address: Temporary failure in name resolution

(Background on this error at: https://sqlalche.me/e/14/e3q8)
[2023-06-11T04:57:48.275+0000] {standard_task_runner.py:109} ERROR - Failed to execute job 368 for task second_task ((psycopg2.OperationalError) could not translate host name "postgres" to address: Temporary failure in name resolution

(Background on this error at: https://sqlalche.me/e/14/e3q8); 1240)
[2023-06-11T04:57:48.635+0000] {local_task_job_runner.py:225} INFO - Task exited with return code 1
[2023-06-11T04:57:48.652+0000] {taskinstance.py:2660} INFO - Skipping mini scheduling run due to exception: None
Traceback (most recent call last):
  File "/home/airflow/.local/lib/python3.7/site-packages/sqlalchemy/engine/base.py", line 3366, in _wrap_pool_connect
    return fn()
  File "/home/airflow/.local/lib/python3.7/site-packages/sqlalchemy/pool/base.py", line 327, in connect
    return _ConnectionFairy._checkout(self)
  File "/home/airflow/.local/lib/python3.7/site-packages/sqlalchemy/pool/base.py", line 894, in _checkout
    fairy = _ConnectionRecord.checkout(pool)
  File "/home/airflow/.local/lib/python3.7/site-packages/sqlalchemy/pool/base.py", line 493, in checkout
    rec = pool._do_get()
  File "/home/airflow/.local/lib/python3.7/site-packages/sqlalchemy/pool/impl.py", line 256, in _do_get
    return self._create_connection()
  File "/home/airflow/.local/lib/python3.7/site-packages/sqlalchemy/pool/base.py", line 273, in _create_connection
    return _ConnectionRecord(self)
  File "/home/airflow/.local/lib/python3.7/site-packages/sqlalchemy/pool/base.py", line 388, in __init__
    self.__connect()
  File "/home/airflow/.local/lib/python3.7/site-packages/sqlalchemy/pool/base.py", line 691, in __connect
    pool.logger.debug("Error on connect(): %s", e)
  File "/home/airflow/.local/lib/python3.7/site-packages/sqlalchemy/util/langhelpers.py", line 72, in __exit__
    with_traceback=exc_tb,
  File "/home/airflow/.local/lib/python3.7/site-packages/sqlalchemy/util/compat.py", line 211, in raise_
    raise exception
  File "/home/airflow/.local/lib/python3.7/site-packages/sqlalchemy/pool/base.py", line 686, in __connect
    self.dbapi_connection = connection = pool._invoke_creator(self)
  File "/home/airflow/.local/lib/python3.7/site-packages/sqlalchemy/engine/create.py", line 574, in connect
    return dialect.connect(*cargs, **cparams)
  File "/home/airflow/.local/lib/python3.7/site-packages/sqlalchemy/engine/default.py", line 598, in connect
    return self.dbapi.connect(*cargs, **cparams)
  File "/home/airflow/.local/lib/python3.7/site-packages/psycopg2/__init__.py", line 122, in connect
    conn = _connect(dsn, connection_factory=connection_factory, **kwasync)
psycopg2.OperationalError: could not translate host name "postgres" to address: Temporary failure in name resolution


The above exception was the direct cause of the following exception:

Traceback (most recent call last):
  File "/home/airflow/.local/lib/python3.7/site-packages/airflow/models/taskinstance.py", line 2611, in schedule_downstream_tasks
    session=session,
  File "/home/airflow/.local/lib/python3.7/site-packages/sqlalchemy/orm/query.py", line 2870, in one
    return self._iter().one()
  File "/home/airflow/.local/lib/python3.7/site-packages/sqlalchemy/orm/query.py", line 2919, in _iter
    execution_options={"_sa_orm_load_options": self.load_options},
  File "/home/airflow/.local/lib/python3.7/site-packages/sqlalchemy/orm/session.py", line 1716, in execute
    conn = self._connection_for_bind(bind)
  File "/home/airflow/.local/lib/python3.7/site-packages/sqlalchemy/orm/session.py", line 1556, in _connection_for_bind
    engine, execution_options
  File "/home/airflow/.local/lib/python3.7/site-packages/sqlalchemy/orm/session.py", line 750, in _connection_for_bind
    conn = bind.connect()
  File "/home/airflow/.local/lib/python3.7/site-packages/sqlalchemy/engine/base.py", line 3320, in connect
    return self._connection_cls(self, close_with_result=close_with_result)
  File "/home/airflow/.local/lib/python3.7/site-packages/sqlalchemy/engine/base.py", line 96, in __init__
    else engine.raw_connection()
  File "/home/airflow/.local/lib/python3.7/site-packages/sqlalchemy/engine/base.py", line 3399, in raw_connection
    return self._wrap_pool_connect(self.pool.connect, _connection)
  File "/home/airflow/.local/lib/python3.7/site-packages/sqlalchemy/engine/base.py", line 3370, in _wrap_pool_connect
    e, dialect, self
  File "/home/airflow/.local/lib/python3.7/site-packages/sqlalchemy/engine/base.py", line 2204, in _handle_dbapi_exception_noconnection
    sqlalchemy_exception, with_traceback=exc_info[2], from_=e
  File "/home/airflow/.local/lib/python3.7/site-packages/sqlalchemy/util/compat.py", line 211, in raise_
    raise exception
  File "/home/airflow/.local/lib/python3.7/site-packages/sqlalchemy/engine/base.py", line 3366, in _wrap_pool_connect
    return fn()
  File "/home/airflow/.local/lib/python3.7/site-packages/sqlalchemy/pool/base.py", line 327, in connect
    return _ConnectionFairy._checkout(self)
  File "/home/airflow/.local/lib/python3.7/site-packages/sqlalchemy/pool/base.py", line 894, in _checkout
    fairy = _ConnectionRecord.checkout(pool)
  File "/home/airflow/.local/lib/python3.7/site-packages/sqlalchemy/pool/base.py", line 493, in checkout
    rec = pool._do_get()
  File "/home/airflow/.local/lib/python3.7/site-packages/sqlalchemy/pool/impl.py", line 256, in _do_get
    return self._create_connection()
  File "/home/airflow/.local/lib/python3.7/site-packages/sqlalchemy/pool/base.py", line 273, in _create_connection
    return _ConnectionRecord(self)
  File "/home/airflow/.local/lib/python3.7/site-packages/sqlalchemy/pool/base.py", line 388, in __init__
    self.__connect()
  File "/home/airflow/.local/lib/python3.7/site-packages/sqlalchemy/pool/base.py", line 691, in __connect
    pool.logger.debug("Error on connect(): %s", e)
  File "/home/airflow/.local/lib/python3.7/site-packages/sqlalchemy/util/langhelpers.py", line 72, in __exit__
    with_traceback=exc_tb,
  File "/home/airflow/.local/lib/python3.7/site-packages/sqlalchemy/util/compat.py", line 211, in raise_
    raise exception
  File "/home/airflow/.local/lib/python3.7/site-packages/sqlalchemy/pool/base.py", line 686, in __connect
    self.dbapi_connection = connection = pool._invoke_creator(self)
  File "/home/airflow/.local/lib/python3.7/site-packages/sqlalchemy/engine/create.py", line 574, in connect
    return dialect.connect(*cargs, **cparams)
  File "/home/airflow/.local/lib/python3.7/site-packages/sqlalchemy/engine/default.py", line 598, in connect
    return self.dbapi.connect(*cargs, **cparams)
  File "/home/airflow/.local/lib/python3.7/site-packages/psycopg2/__init__.py", line 122, in connect
    conn = _connect(dsn, connection_factory=connection_factory, **kwasync)
sqlalchemy.exc.OperationalError: (psycopg2.OperationalError) could not translate host name "postgres" to address: Temporary failure in name resolution

(Background on this error at: https://sqlalche.me/e/14/e3q8)
[2023-06-11T08:53:27.832+0000] {taskinstance.py:1103} INFO - Dependencies all met for dep_context=non-requeueable deps ti=<TaskInstance: first_dag_02.second_task scheduled__2021-11-03T00:00:00+00:00 [queued]>
[2023-06-11T08:53:27.999+0000] {taskinstance.py:1103} INFO - Dependencies all met for dep_context=requeueable deps ti=<TaskInstance: first_dag_02.second_task scheduled__2021-11-03T00:00:00+00:00 [queued]>
[2023-06-11T08:53:28.000+0000] {taskinstance.py:1308} INFO - Starting attempt 1 of 6
[2023-06-11T08:53:28.587+0000] {taskinstance.py:1327} INFO - Executing <Task(BashOperator): second_task> on 2021-11-03 00:00:00+00:00
[2023-06-11T08:53:28.665+0000] {standard_task_runner.py:57} INFO - Started process 1580 to run task
[2023-06-11T08:53:28.741+0000] {standard_task_runner.py:84} INFO - Running: ['***', 'tasks', 'run', 'first_dag_02', 'second_task', 'scheduled__2021-11-03T00:00:00+00:00', '--job-id', '487', '--raw', '--subdir', 'DAGS_FOLDER/First_dag.py', '--cfg-path', '/tmp/tmpged80uzd']
[2023-06-11T08:53:28.742+0000] {standard_task_runner.py:85} INFO - Job 487: Subtask second_task
[2023-06-11T08:53:29.485+0000] {task_command.py:410} INFO - Running <TaskInstance: first_dag_02.second_task scheduled__2021-11-03T00:00:00+00:00 [running]> on host 964e508aad03
[2023-06-11T08:53:31.902+0000] {taskinstance.py:1547} INFO - Exporting env vars: AIRFLOW_CTX_DAG_OWNER='Raja' AIRFLOW_CTX_DAG_ID='first_dag_02' AIRFLOW_CTX_TASK_ID='second_task' AIRFLOW_CTX_EXECUTION_DATE='2021-11-03T00:00:00+00:00' AIRFLOW_CTX_TRY_NUMBER='1' AIRFLOW_CTX_DAG_RUN_ID='scheduled__2021-11-03T00:00:00+00:00'
[2023-06-11T08:53:31.904+0000] {subprocess.py:63} INFO - Tmp dir root location: 
 /tmp
[2023-06-11T08:53:31.914+0000] {subprocess.py:75} INFO - Running command: ['/bin/bash', '-c', 'echo hey, I am task2 and will be running after task1!']
[2023-06-11T08:53:32.111+0000] {subprocess.py:86} INFO - Output:
[2023-06-11T08:53:32.167+0000] {subprocess.py:93} INFO - hey, I am task2 and will be running after task1!
[2023-06-11T08:53:32.173+0000] {subprocess.py:97} INFO - Command exited with return code 0
[2023-06-11T08:53:32.609+0000] {taskinstance.py:1350} INFO - Marking task as SUCCESS. dag_id=first_dag_02, task_id=second_task, execution_date=20211103T000000, start_date=20230611T085327, end_date=20230611T085332
[2023-06-11T08:53:33.006+0000] {local_task_job_runner.py:225} INFO - Task exited with return code 0
[2023-06-11T08:53:33.370+0000] {taskinstance.py:2651} INFO - 0 downstream tasks scheduled from follow-on schedule check
[2023-06-11T11:18:16.242+0000] {taskinstance.py:1103} INFO - Dependencies all met for dep_context=non-requeueable deps ti=<TaskInstance: first_dag_02.second_task scheduled__2021-11-03T00:00:00+00:00 [queued]>
[2023-06-11T11:18:17.271+0000] {taskinstance.py:1103} INFO - Dependencies all met for dep_context=requeueable deps ti=<TaskInstance: first_dag_02.second_task scheduled__2021-11-03T00:00:00+00:00 [queued]>
[2023-06-11T11:18:17.289+0000] {taskinstance.py:1308} INFO - Starting attempt 1 of 6
[2023-06-11T11:18:18.323+0000] {taskinstance.py:1327} INFO - Executing <Task(BashOperator): second_task> on 2021-11-03 00:00:00+00:00
[2023-06-11T11:18:18.391+0000] {standard_task_runner.py:57} INFO - Started process 682 to run task
[2023-06-11T11:18:18.560+0000] {standard_task_runner.py:84} INFO - Running: ['***', 'tasks', 'run', 'first_dag_02', 'second_task', 'scheduled__2021-11-03T00:00:00+00:00', '--job-id', '661', '--raw', '--subdir', 'DAGS_FOLDER/First_dag.py', '--cfg-path', '/tmp/tmp_cw9b641']
[2023-06-11T11:18:18.598+0000] {standard_task_runner.py:85} INFO - Job 661: Subtask second_task
[2023-06-11T11:18:21.365+0000] {task_command.py:410} INFO - Running <TaskInstance: first_dag_02.second_task scheduled__2021-11-03T00:00:00+00:00 [running]> on host 7586ce0070ac
[2023-06-11T11:18:24.842+0000] {taskinstance.py:1547} INFO - Exporting env vars: AIRFLOW_CTX_DAG_OWNER='Raja' AIRFLOW_CTX_DAG_ID='first_dag_02' AIRFLOW_CTX_TASK_ID='second_task' AIRFLOW_CTX_EXECUTION_DATE='2021-11-03T00:00:00+00:00' AIRFLOW_CTX_TRY_NUMBER='1' AIRFLOW_CTX_DAG_RUN_ID='scheduled__2021-11-03T00:00:00+00:00'
[2023-06-11T11:18:24.850+0000] {subprocess.py:63} INFO - Tmp dir root location: 
 /tmp
[2023-06-11T11:18:24.854+0000] {subprocess.py:75} INFO - Running command: ['/bin/bash', '-c', 'echo hey, I am task2 and will be running after task1!']
[2023-06-11T11:18:25.230+0000] {subprocess.py:86} INFO - Output:
[2023-06-11T11:18:25.506+0000] {subprocess.py:93} INFO - hey, I am task2 and will be running after task1!
[2023-06-11T11:18:25.571+0000] {subprocess.py:97} INFO - Command exited with return code 0
[2023-06-11T11:18:25.985+0000] {taskinstance.py:1350} INFO - Marking task as SUCCESS. dag_id=first_dag_02, task_id=second_task, execution_date=20211103T000000, start_date=20230611T111816, end_date=20230611T111825
[2023-06-11T11:18:26.324+0000] {local_task_job_runner.py:225} INFO - Task exited with return code 0
[2023-06-11T11:18:27.318+0000] {taskinstance.py:2651} INFO - 0 downstream tasks scheduled from follow-on schedule check
